Workbook

Sheet 充放测算
A1: 储能每日充放测算
A2: 充电支出 | L2: 放电收入 | O2: 现货收益 | P2: 其他
A3: 充电均价 (元/MWh) | B3: 充电电量(MWh) | C3: 交易充电 费用(元) | D3: 优发优购(元) | E3: 上网线损(元) | F3: 输配电费(元) | G3: 政府基金(元) | H3: 系统运行(元) | I3: 容量分摊(元) | J3: 容量分摊 系数 | K3: 充电总 费用(元) | L3: 放电均价 (元/MWh) | M3: 放电电量(MWh) | N3: 放电电费 (元) | O3: （元） | P3: 综合效率 | Q3: 充放价差 (元/MWh)
A4: =报价及预中标!B26 | B4: =报价及预中标!B25 | C4: =A4*B4 | D4: =$B$4*I12 | E4: =$B$4*I13 | F4: =B4*(1-P4)*I8 | G4: =B4*(1-P4)*I9 | H4: =$B$4*I14 | I4: =B4*J4*70.5 | J4: =容量分摊系数!G3 | K4: =C4+D4+E4+F4+G4+H4+I4 | L4: =报价及预中标!D26 | M4: =报价及预中标!D25 | N4: =L4*M4 | O4: =N4+K4 | P4: =-M4/B4 | Q4: =L4-A4
A6: 说明 | B6: 根据预测电价，输入充电均价，放电均价。根据充电时段计算出对于的容量分摊系数，计入容量分摊。 | K6: =K3
A7: 1 | B7: 充电均价（元 / MWh）输入限制：-100 至 800； | K7: =C3
A8: 2 | B8: 输配电价（元 / MWh）设置：收取损耗部分输配电价； | I8: 191.9 | J8: 政府核定 | K8: =D3
A9: 3 | B9: 政府基金（元 /M Wh）设置：收取损耗部分输配电价； | I9: 27.168 | J9: 政府核定 | K9: =E3
A10: 4 | B10: 综合效率设置：60% 至 100%； | K10: =F3
A11: 5 | B11: 放电均价（元 / MWh）输入限制：100 至 1500； | K11: =G3
A12: 6 | B12: 优发优购曲线匹配偏差标准：暂以上月替代； | I12: 3.5 | J12: 上月均值 | K12: =H3
A13: 7 | B13: 上网环节线损费用； | I13: 3.3 | J13: 上月均值 | K13: =I3
A14: 8 | B14: 系统运行费用； | I14: -2.9 | J14: 上月均值
A15: 9 | B15: 容量分摊：按季度分为4种类型，详见附表；
A16: 10 | B16: 根据选择的充电时段，计算容量分摊系数。

Sheet 报价及预中标
A1: 假设 | G1: 时点序号 | I1: 时点 | J1: 统一结算日前 | K1: 节点日前电价 | L1: 真实充电中标 | M1: 真实放电中标 | N1: 充放电曲线
A2: 1. 中标按最大值中标，如[-100,-95],按-100中标，[0,95]，按95中标 | G2: 1 | H2: 20250922 0015 | I2: =RIGHT(H2,4) | J2: 632 | K2: 632 | L2: =IF(N2<=0, N2, 0) | M2: =IF(N2>=0, N2, 0) | N2: 0
G3: 2 | H3: 20250922 0030 | I3: =RIGHT(H3,4) | J3: 617.67 | K3: 617.67 | L3: =IF(N3<=0, N3, 0) | M3: =IF(N3>=0, N3, 0) | N3: 0
G4: 3 | H4: 20250922 0045 | I4: =RIGHT(H4,4) | J4: 615 | K4: 615 | L4: =IF(N4<=0, N4, 0) | M4: =IF(N4>=0, N4, 0) | N4: 0
A5: 序号 | B5: 类型 | C5: 开始出力（MW） | D5: 结束出力（MW） | E5: 报价（元/MWh） | G5: 4 | H5: 20250922 0100 | I5: =RIGHT(H5,4) | J5: 610 | K5: 610 | L5: =IF(N5<=0, N5, 0) | M5: =IF(N5>=0, N5, 0) | N5: 0
A6: 1 | B6: 充电 | C6: -100 | D6: -95 | E6: 0 | G6: 5 | H6: 20250922 0115 | I6: =RIGHT(H6,4) | J6: 608 | K6: 608 | L6: =IF(N6<=0, N6, 0) | M6: =IF(N6>=0, N6, 0) | N6: 0
A7: 2 | B7: 充电 | C7: -95 | D7: 0 | E7: 100 | G7: 6 | H7: 20250922 0130 | I7: =RIGHT(H7,4) | J7: 604.5 | K7: 604.5 | L7: =IF(N7<=0, N7, 0) | M7: =IF(N7>=0, N7, 0) | N7: 0
A8: 3 | B8: 充电 | G8: 7 | H8: 20250922 0145 | I8: =RIGHT(H8,4) | J8: 604 | K8: 604 | L8: =IF(N8<=0, N8, 0) | M8: =IF(N8>=0, N8, 0) | N8: 0
A9: 4 | B9: 充电 | G9: 8 | H9: 20250922 0200 | I9: =RIGHT(H9,4) | J9: 604 | K9: 604 | L9: =IF(N9<=0, N9, 0) | M9: =IF(N9>=0, N9, 0) | N9: 0
A10: 5 | B10: 充电 | G10: 9 | H10: 20250922 0215 | I10: =RIGHT(H10,4) | J10: 602 | K10: 602 | L10: =IF(N10<=0, N10, 0) | M10: =IF(N10>=0, N10, 0) | N10: 0
A11: 6 | B11: 放电 | C11: 0 | D11: 95 | E11: 250 | G11: 10 | H11: 20250922 0230 | I11: =RIGHT(H11,4) | J11: 602 | K11: 602 | L11: =IF(N11<=0, N11, 0) | M11: =IF(N11>=0, N11, 0) | N11: 0
A12: 7 | B12: 放电 | C12: 95 | D12: 100 | E12: 300 | G12: 11 | H12: 20250922 0245 | I12: =RIGHT(H12,4) | J12: 600.5 | K12: 600.5 | L12: =IF(N12<=0, N12, 0) | M12: =IF(N12>=0, N12, 0) | N12: 0
A13: 8 | B13: 放电 | G13: 12 | H13: 20250922 0300 | I13: =RIGHT(H13,4) | J13: 599 | K13: 599 | L13: =IF(N13<=0, N13, 0) | M13: =IF(N13>=0, N13, 0) | N13: 0
A14: 9 | B14: 放电 | G14: 13 | H14: 20250922 0315 | I14: =RIGHT(H14,4) | J14: 599 | K14: 599 | L14: =IF(N14<=0, N14, 0) | M14: =IF(N14>=0, N14, 0) | N14: 0
A15: 10 | B15: 放电 | G15: 14 | H15: 20250922 0330 | I15: =RIGHT(H15,4) | J15: 598 | K15: 598 | L15: =IF(N15<=0, N15, 0) | M15: =IF(N15>=0, N15, 0) | N15: 0
G16: 15 | H16: 20250922 0345 | I16: =RIGHT(H16,4) | J16: 599.29 | K16: 599.29 | L16: =IF(N16<=0, N16, 0) | M16: =IF(N16>=0, N16, 0) | N16: 0
G17: 16 | H17: 20250922 0400 | I17: =RIGHT(H17,4) | J17: 602 | K17: 602 | L17: =IF(N17<=0, N17, 0) | M17: =IF(N17>=0, N17, 0) | N17: 0
A18: 初始电量（MWh) | B18: 0 | G18: 17 | H18: 20250922 0415 | I18: =RIGHT(H18,4) | J18: 604 | K18: 604 | L18: =IF(N18<=0, N18, 0) | M18: =IF(N18>=0, N18, 0) | N18: 0
A19: 额定装机（MW） | B19: 100 | G19: 18 | H19: 20250922 0430 | I19: =RIGHT(H19,4) | J19: 608.5 | K19: 608.5 | L19: =IF(N19<=0, N19, 0) | M19: =IF(N19>=0, N19, 0) | N19: 0
A20: 最大电量（MWh) | B20: 180 | G20: 19 | H20: 20250922 0445 | I20: =RIGHT(H20,4) | J20: 612 | K20: 612 | L20: =IF(N20<=0, N20, 0) | M20: =IF(N20>=0, N20, 0) | N20: 0
A21: 综合使用效率 | B21: 0.9 | G21: 20 | H21: 20250922 0500 | I21: =RIGHT(H21,4) | J21: 616 | K21: 616 | L21: =IF(N21<=0, N21, 0) | M21: =IF(N21>=0, N21, 0) | N21: 0
G22: 21 | H22: 20250922 0515 | I22: =RIGHT(H22,4) | J22: 617 | K22: 617 | L22: =IF(N22<=0, N22, 0) | M22: =IF(N22>=0, N22, 0) | N22: 9.49
G23: 22 | H23: 20250922 0530 | I23: =RIGHT(H23,4) | J23: 617 | K23: 617 | L23: =IF(N23<=0, N23, 0) | M23: =IF(N23>=0, N23, 0) | N23: 0
G24: 23 | H24: 20250922 0545 | I24: =RIGHT(H24,4) | J24: 609.18 | K24: 609.18 | L24: =IF(N24<=0, N24, 0) | M24: =IF(N24>=0, N24, 0) | N24: 0
A25: 充电电量（MWh) | B25: =SUM(L:L)/4 | C25: 放电电量（MWh) | D25: =SUM(M:M)/4 | G25: 24 | H25: 20250922 0600 | I25: =RIGHT(H25,4) | J25: 601.35 | K25: 601.35 | L25: =IF(N25<=0, N25, 0) | M25: =IF(N25>=0, N25, 0) | N25: 0
A26: 充电均价(元/MWh） | B26: =B27/B25 | C26: 放电均价(元/MWh） | D26: =D27/D25 | G26: 25 | H26: 20250922 0615 | I26: =RIGHT(H26,4) | J26: 587 | K26: 587 | L26: =IF(N26<=0, N26, 0) | M26: =IF(N26>=0, N26, 0) | N26: 0
A27: 充电费用（元,正数代表收入） | B27: =SUMPRODUCT(J:J,L:L)/4 | C27: 放电收益（元,正数代表收入） | D27: {=SUMPRODUCT(K:K,M:M)/4} | G27: 26 | H27: 20250922 0630 | I27: =RIGHT(H27,4) | J27: 557 | K27: 557 | L27: =IF(N27<=0, N27, 0) | M27: =IF(N27>=0, N27, 0) | N27: 0
A28: 充放电价差(元/MWh） | B28: =D26-B26 | C28: 充放电收益(元/MWh） | D28: =D27+B27 | G28: 27 | H28: 20250922 0645 | I28: =RIGHT(H28,4) | J28: 522 | K28: 522 | L28: =IF(N28<=0, N28, 0) | M28: =IF(N28>=0, N28, 0) | N28: 0
G29: 28 | H29: 20250922 0700 | I29: =RIGHT(H29,4) | J29: 457.8 | K29: 457.8 | L29: =IF(N29<=0, N29, 0) | M29: =IF(N29>=0, N29, 0) | N29: 0
D30: =充放测算!O4 | G30: 29 | H30: 20250922 0715 | I30: =RIGHT(H30,4) | J30: 394.9 | K30: 394.9 | L30: =IF(N30<=0, N30, 0) | M30: =IF(N30>=0, N30, 0) | N30: 0
G31: 30 | H31: 20250922 0730 | I31: =RIGHT(H31,4) | J31: 374.33 | K31: 374.33 | L31: =IF(N31<=0, N31, 0) | M31: =IF(N31>=0, N31, 0) | N31: 0
G32: 31 | H32: 20250922 0745 | I32: =RIGHT(H32,4) | J32: 341.2 | K32: 341.2 | L32: =IF(N32<=0, N32, 0) | M32: =IF(N32>=0, N32, 0) | N32: 0
G33: 32 | H33: 20250922 0800 | I33: =RIGHT(H33,4) | J33: 345.18 | K33: 345.18 | L33: =IF(N33<=0, N33, 0) | M33: =IF(N33>=0, N33, 0) | N33: 0
A34: 序号 | B34: 类型 | C34: 开始出力（MW） | D34: 结束出力（MW） | E34: 报价(元/MWh) | G34: 33 | H34: 20250922 0815 | I34: =RIGHT(H34,4) | J34: 341.39 | K34: 341.39 | L34: =IF(N34<=0, N34, 0) | M34: =IF(N34>=0, N34, 0) | N34: 0
G35: 34 | H35: 20250922 0830 | I35: =RIGHT(H35,4) | J35: 200.05 | K35: 200.05 | L35: =IF(N35<=0, N35, 0) | M35: =IF(N35>=0, N35, 0) | N35: 0
A36: 1 | B36: 充电 | C36: -100 | D36: -95 | E36: 0 | G36: 35 | H36: 20250922 0845 | I36: =RIGHT(H36,4) | J36: -78.15 | K36: -78.15 | L36: =IF(N36<=0, N36, 0) | M36: =IF(N36>=0, N36, 0) | N36: 0
A37: 2 | B37: 充电 | C37: -95 | D37: 0 | E37: 150 | G37: 36 | H37: 20250922 0900 | I37: =RIGHT(H37,4) | J37: -80 | K37: -80 | L37: =IF(N37<=0, N37, 0) | M37: =IF(N37>=0, N37, 0) | N37: 0
A38: 3 | B38: 放电 | C38: 0 | D38: 95 | E38: 280 | G38: 37 | H38: 20250922 0915 | I38: =RIGHT(H38,4) | J38: -100 | K38: -100 | L38: =IF(N38<=0, N38, 0) | M38: =IF(N38>=0, N38, 0) | N38: 0
A39: 4 | B39: 放电 | C39: 95 | D39: 100 | E39: 350 | G39: 38 | H39: 20250922 0930 | I39: =RIGHT(H39,4) | J39: -100 | K39: -100 | L39: =IF(N39<=0, N39, 0) | M39: =IF(N39>=0, N39, 0) | N39: 0
G40: 39 | H40: 20250922 0945 | I40: =RIGHT(H40,4) | J40: -100 | K40: -100 | L40: =IF(N40<=0, N40, 0) | M40: =IF(N40>=0, N40, 0) | N40: 0
...

Sheet 容量分摊系数
A1: 容量电价 | C1: 70.5
A3: 容量分摊--算数平均 系数 | C3: {=SUMPRODUCT(C8:C103,D8:D103)/SUM(C8:C103)} | E3: 容量分摊系数--电量加权 | G3: {=SUMPRODUCT(D8:D103,E8:E103)/SUM(E8:E103)}
A6: 时点 | B6: 刻钟点 | C6: 是否充电 | D6: 当前月份 | E6: 充电电量 | F6: 容量分摊系数（2026年）
D7: 5月 | F7: 1月 | G7: 2月 | H7: 3月 | I7: 4月 | J7: 5月 | K7: 6月 | L7: 7月 | M7: 8月 | N7: 9月 | O7: 10月 | P7: 11月 | Q7: 12月
A8: 1 | B8: 1 | C8: =IF(E8<0,1,0) | D8: {=INDIRECT(ADDRESS(B8+ROW($D$7),MATCH($D$7,$F$7:$Q$7,0)+5))} | E8: =报价及预中标!L2/4 | F8: 1 | G8: 1 | H8: 1 | I8: 1 | J8: 1 | K8: 1 | L8: 0.3 | M8: 0.3 | N8: 1 | O8: 1 | P8: 1 | Q8: 1
B9: 2 | C9: =IF(E9<0,1,0) | D9: {=INDIRECT(ADDRESS(B9+ROW($D$7),MATCH($D$7,$F$7:$Q$7,0)+5))} | E9: =报价及预中标!L3/4 | F9: 1 | G9: 1 | H9: 1 | I9: 1 | J9: 1 | K9: 1 | L9: 0.3 | M9: 0.3 | N9: 1 | O9: 1 | P9: 1 | Q9: 1
B10: 3 | C10: =IF(E10<0,1,0) | D10: {=INDIRECT(ADDRESS(B10+ROW($D$7),MATCH($D$7,$F$7:$Q$7,0)+5))} | E10: =报价及预中标!L4/4 | F10: 1 | G10: 1 | H10: 1 | I10: 1 | J10: 1 | K10: 1 | L10: 0.3 | M10: 0.3 | N10: 1 | O10: 1 | P10: 1 | Q10: 1
B11: 4 | C11: =IF(E11<0,1,0) | D11: {=INDIRECT(ADDRESS(B11+ROW($D$7),MATCH($D$7,$F$7:$Q$7,0)+5))} | E11: =报价及预中标!L5/4 | F11: 1 | G11: 1 | H11: 1 | I11: 1 | J11: 1 | K11: 1 | L11: 0.3 | M11: 0.3 | N11: 1 | O11: 1 | P11: 1 | Q11: 1
A12: 2 | B12: 5 | C12: =IF(E12<0,1,0) | D12: {=INDIRECT(ADDRESS(B12+ROW($D$7),MATCH($D$7,$F$7:$Q$7,0)+5))} | E12: =报价及预中标!L6/4 | F12: 0.3 | G12: 0.3 | H12: 1 | I12: 1 | J12: 1 | K12: 1 | L12: 0.3 | M12: 0.3 | N12: 1 | O12: 1 | P12: 1 | Q12: 0.3
B13: 6 | C13: =IF(E13<0,1,0) | D13: {=INDIRECT(ADDRESS(B13+ROW($D$7),MATCH($D$7,$F$7:$Q$7,0)+5))} | E13: =报价及预中标!L7/4 | F13: 0.3 | G13: 0.3 | H13: 1 | I13: 1 | J13: 1 | K13: 1 | L13: 0.3 | M13: 0.3 | N13: 1 | O13: 1 | P13: 1 | Q13: 0.3
B14: 7 | C14: =IF(E14<0,1,0) | D14: {=INDIRECT(ADDRESS(B14+ROW($D$7),MATCH($D$7,$F$7:$Q$7,0)+5))} | E14: =报价及预中标!L8/4 | F14: 0.3 | G14: 0.3 | H14: 1 | I14: 1 | J14: 1 | K14: 1 | L14: 0.3 | M14: 0.3 | N14: 1 | O14: 1 | P14: 1 | Q14: 0.3
B15: 8 | C15: =IF(E15<0,1,0) | D15: {=INDIRECT(ADDRESS(B15+ROW($D$7),MATCH($D$7,$F$7:$Q$7,0)+5))} | E15: =报价及预中标!L9/4 | F15: 0.3 | G15: 0.3 | H15: 1 | I15: 1 | J15: 1 | K15: 1 | L15: 0.3 | M15: 0.3 | N15: 1 | O15: 1 | P15: 1 | Q15: 0.3
A16: 3 | B16: 9 | C16: =IF(E16<0,1,0) | D16: {=INDIRECT(ADDRESS(B16+ROW($D$7),MATCH($D$7,$F$7:$Q$7,0)+5))} | E16: =报价及预中标!L10/4 | F16: 0.3 | G16: 0.3 | H16: 1 | I16: 1 | J16: 1 | K16: 1 | L16: 0.3 | M16: 0.3 | N16: 1 | O16: 1 | P16: 1 | Q16: 0.3
B17: 10 | C17: =IF(E17<0,1,0) | D17: {=INDIRECT(ADDRESS(B17+ROW($D$7),MATCH($D$7,$F$7:$Q$7,0)+5))} | E17: =报价及预中标!L11/4 | F17: 0.3 | G17: 0.3 | H17: 1 | I17: 1 | J17: 1 | K17: 1 | L17: 0.3 | M17: 0.3 | N17: 1 | O17: 1 | P17: 1 | Q17: 0.3
B18: 11 | C18: =IF(E18<0,1,0) | D18: {=INDIRECT(ADDRESS(B18+ROW($D$7),MATCH($D$7,$F$7:$Q$7,0)+5))} | E18: =报价及预中标!L12/4 | F18: 0.3 | G18: 0.3 | H18: 1 | I18: 1 | J18: 1 | K18: 1 | L18: 0.3 | M18: 0.3 | N18: 1 | O18: 1 | P18: 1 | Q18: 0.3
B19: 12 | C19: =IF(E19<0,1,0) | D19: {=INDIRECT(ADDRESS(B19+ROW($D$7),MATCH($D$7,$F$7:$Q$7,0)+5))} | E19: =报价及预中标!L13/4 | F19: 0.3 | G19: 0.3 | H19: 1 | I19: 1 | J19: 1 | K19: 1 | L19: 0.3 | M19: 0.3 | N19: 1 | O19: 1 | P19: 1 | Q19: 0.3
A20: 4 | B20: 13 | C20: =IF(E20<0,1,0) | D20: {=INDIRECT(ADDRESS(B20+ROW($D$7),MATCH($D$7,$F$7:$Q$7,0)+5))} | E20: =报价及预中标!L14/4 | F20: 0.3 | G20: 0.3 | H20: 1 | I20: 1 | J20: 1 | K20: 1 | L20: 0.3 | M20: 0.3 | N20: 1 | O20: 1 | P20: 1 | Q20: 0.3
B21: 14 | C21: =IF(E21<0,1,0) | D21: {=INDIRECT(ADDRESS(B21+ROW($D$7),MATCH($D$7,$F$7:$Q$7,0)+5))} | E21: =报价及预中标!L15/4 | F21: 0.3 | G21: 0.3 | H21: 1 | I21: 1 | J21: 1 | K21: 1 | L21: 0.3 | M21: 0.3 | N21: 1 | O21: 1 | P21: 1 | Q21: 0.3
B22: 15 | C22: =IF(E22<0,1,0) | D22: {=INDIRECT(ADDRESS(B22+ROW($D$7),MATCH($D$7,$F$7:$Q$7,0)+5))} | E22: =报价及预中标!L16/4 | F22: 0.3 | G22: 0.3 | H22: 1 | I22: 1 | J22: 1 | K22: 1 | L22: 0.3 | M22: 0.3 | N22: 1 | O22: 1 | P22: 1 | Q22: 0.3
B23: 16 | C23: =IF(E23<0,1,0) | D23: {=INDIRECT(ADDRESS(B23+ROW($D$7),MATCH($D$7,$F$7:$Q$7,0)+5))} | E23: =报价及预中标!L17/4 | F23: 0.3 | G23: 0.3 | H23: 1 | I23: 1 | J23: 1 | K23: 1 | L23: 0.3 | M23: 0.3 | N23: 1 | O23: 1 | P23: 1 | Q23: 0.3
A24: 5 | B24: 17 | C24: =IF(E24<0,1,0) | D24: {=INDIRECT(ADDRESS(B24+ROW($D$7),MATCH($D$7,$F$7:$Q$7,0)+5))} | E24: =报价及预中标!L18/4 | F24: 0.3 | G24: 0.3 | H24: 1 | I24: 1 | J24: 1 | K24: 1 | L24: 0.3 | M24: 0.3 | N24: 1 | O24: 1 | P24: 1 | Q24: 0.3
B25: 18 | C25: =IF(E25<0,1,0) | D25: {=INDIRECT(ADDRESS(B25+ROW($D$7),MATCH($D$7,$F$7:$Q$7,0)+5))} | E25: =报价及预中标!L19/4 | F25: 0.3 | G25: 0.3 | H25: 1 | I25: 1 | J25: 1 | K25: 1 | L25: 0.3 | M25: 0.3 | N25: 1 | O25: 1 | P25: 1 | Q25: 0.3
B26: 19 | C26: =IF(E26<0,1,0) | D26: {=INDIRECT(ADDRESS(B26+ROW($D$7),MATCH($D$7,$F$7:$Q$7,0)+5))} | E26: =报价及预中标!L20/4 | F26: 0.3 | G26: 0.3 | H26: 1 | I26: 1 | J26: 1 | K26: 1 | L26: 0.3 | M26: 0.3 | N26: 1 | O26: 1 | P26: 1 | Q26: 0.3
B27: 20 | C27: =IF(E27<0,1,0) | D27: {=INDIRECT(ADDRESS(B27+ROW($D$7),MATCH($D$7,$F$7:$Q$7,0)+5))} | E27: =报价及预中标!L21/4 | F27: 0.3 | G27: 0.3 | H27: 1 | I27: 1 | J27: 1 | K27: 1 | L27: 0.3 | M27: 0.3 | N27: 1 | O27: 1 | P27: 1 | Q27: 0.3
A28: 6 | B28: 21 | C28: =IF(E28<0,1,0) | D28: {=INDIRECT(ADDRESS(B28+ROW($D$7),MATCH($D$7,$F$7:$Q$7,0)+5))} | E28: =报价及预中标!L22/4 | F28: 0.3 | G28: 0.3 | H28: 1 | I28: 1 | J28: 1 | K28: 1 | L28: 0.3 | M28: 0.3 | N28: 1 | O28: 1 | P28: 1 | Q28: 0.3
B29: 22 | C29: =IF(E29<0,1,0) | D29: {=INDIRECT(ADDRESS(B29+ROW($D$7),MATCH($D$7,$F$7:$Q$7,0)+5))} | E29: =报价及预中标!L23/4 | F29: 0.3 | G29: 0.3 | H29: 1 | I29: 1 | J29: 1 | K29: 1 | L29: 0.3 | M29: 0.3 | N29: 1 | O29: 1 | P29: 1 | Q29: 0.3
B30: 23 | C30: =IF(E30<0,1,0) | D30: {=INDIRECT(ADDRESS(B30+ROW($D$7),MATCH($D$7,$F$7:$Q$7,0)+5))} | E30: =报价及预中标!L24/4 | F30: 0.3 | G30: 0.3 | H30: 1 | I30: 1 | J30: 1 | K30: 1 | L30: 0.3 | M30: 0.3 | N30: 1 | O30: 1 | P30: 1 | Q30: 0.3
B31: 24 | C31: =IF(E31<0,1,0) | D31: {=INDIRECT(ADDRESS(B31+ROW($D$7),MATCH($D$7,$F$7:$Q$7,0)+5))} | E31: =报价及预中标!L25/4 | F31: 0.3 | G31: 0.3 | H31: 1 | I31: 1 | J31: 1 | K31: 1 | L31: 0.3 | M31: 0.3 | N31: 1 | O31: 1 | P31: 1 | Q31: 0.3
A32: 7 | B32: 25 | C32: =IF(E32<0,1,0) | D32: {=INDIRECT(ADDRESS(B32+ROW($D$7),MATCH($D$7,$F$7:$Q$7,0)+5))} | E32: =报价及预中标!L26/4 | F32: 1.7 | G32: 1.7 | H32: 1 | I32: 1 | J32: 1 | K32: 0.3 | L32: 1 | M32: 1 | N32: 1 | O32: 1 | P32: 1 | Q32: 1.7
B33: 26 | C33: =IF(E33<0,1,0) | D33: {=INDIRECT(ADDRESS(B33+ROW($D$7),MATCH($D$7,$F$7:$Q$7,0)+5))} | E33: =报价及预中标!L27/4 | F33: 1.7 | G33: 1.7 | H33: 1 | I33: 1 | J33: 1 | K33: 0.3 | L33: 1 | M33: 1 | N33: 1 | O33: 1 | P33: 1 | Q33: 1.7
B34: 27 | C34: =IF(E34<0,1,0) | D34: {=INDIRECT(ADDRESS(B34+ROW($D$7),MATCH($D$7,$F$7:$Q$7,0)+5))} | E34: =报价及预中标!L28/4 | F34: 1.7 | G34: 1.7 | H34: 1 | I34: 1 | J34: 1 | K34: 0.3 | L34: 1 | M34: 1 | N34: 1 | O34: 1 | P34: 1 | Q34: 1.7
B35: 28 | C35: =IF(E35<0,1,0) | D35: {=INDIRECT(ADDRESS(B35+ROW($D$7),MATCH($D$7,$F$7:$Q$7,0)+5))} | E35: =报价及预中标!L29/4 | F35: 1.7 | G35: 1.7 | H35: 1 | I35: 1 | J35: 1 | K35: 0.3 | L35: 1 | M35: 1 | N35: 1 | O35: 1 | P35: 1 | Q35: 1.7
A36: 8 | B36: 29 | C36: =IF(E36<0,1,0) | D36: {=INDIRECT(ADDRESS(B36+ROW($D$7),MATCH($D$7,$F$7:$Q$7,0)+5))} | E36: =报价及预中标!L30/4 | F36: 1.7 | G36: 1.7 | H36: 1 | I36: 1 | J36: 1 | K36: 0.3 | L36: 1 | M36: 1 | N36: 1 | O36: 1 | P36: 1 | Q36: 1.7
B37: 30 | C37: =IF(E37<0,1,0) | D37: {=INDIRECT(ADDRESS(B37+ROW($D$7),MATCH($D$7,$F$7:$Q$7,0)+5))} | E37: =报价及预中标!L31/4 | F37: 1.7 | G37: 1.7 | H37: 1 | I37: 1 | J37: 1 | K37: 0.3 | L37: 1 | M37: 1 | N37: 1 | O37: 1 | P37: 1 | Q37: 1.7
B38: 31 | C38: =IF(E38<0,1,0) | D38: {=INDIRECT(ADDRESS(B38+ROW($D$7),MATCH($D$7,$F$7:$Q$7,0)+5))} | E38: =报价及预中标!L32/4 | F38: 1.7 | G38: 1.7 | H38: 1 | I38: 1 | J38: 1 | K38: 0.3 | L38: 1 | M38: 1 | N38: 1 | O38: 1 | P38: 1 | Q38: 1.7
B39: 32 | C39: =IF(E39<0,1,0) | D39: {=INDIRECT(ADDRESS(B39+ROW($D$7),MATCH($D$7,$F$7:$Q$7,0)+5))} | E39: =报价及预中标!L33/4 | F39: 1.7 | G39: 1.7 | H39: 1 | I39: 1 | J39: 1 | K39: 0.3 | L39: 1 | M39: 1 | N39: 1 | O39: 1 | P39: 1 | Q39: 1.7
A40: 9 | B40: 33 | C40: =IF(E40<0,1,0) | D40: {=INDIRECT(ADDRESS(B40+ROW($D$7),MATCH($D$7,$F$7:$Q$7,0)+5))} | E40: =报价及预中标!L34/4 | F40: 1.7 | G40: 1.7 | H40: 1 | I40: 1 | J40: 1 | K40: 0.3 | L40: 1 | M40: 1 | N40: 1 | O40: 1 | P40: 1 | Q40: 1.7
B41: 34 | C41: =IF(E41<0,1,0) | D41: {=INDIRECT(ADDRESS(B41+ROW($D$7),MATCH($D$7,$F$7:$Q$7,0)+5))} | E41: =报价及预中标!L35/4 | F41: 1.7 | G41: 1.7 | H41: 1 | I41: 1 | J41: 1 | K41: 0.3 | L41: 1 | M41: 1 | N41: 1 | O41: 1 | P41: 1 | Q41: 1.7
B42: 35 | C42: =IF(E42<0,1,0) | D42: {=INDIRECT(ADDRESS(B42+ROW($D$7),MATCH($D$7,$F$7:$Q$7,0)+5))} | E42: =报价及预中标!L36/4 | F42: 1.7 | G42: 1.7 | H42: 1 | I42: 1 | J42: 1 | K42: 0.3 | L42: 1 | M42: 1 | N42: 1 | O42: 1 | P42: 1 | Q42: 1.7
B43: 36 | C43: =IF(E43<0,1,0) | D43: {=INDIRECT(ADDRESS(B43+ROW($D$7),MATCH($D$7,$F$7:$Q$7,0)+5))} | E43: =报价及预中标!L37/4 | F43: 1.7 | G43: 1.7 | H43: 1 | I43: 1 | J43: 1 | K43: 0.3 | L43: 1 | M43: 1 | N43: 1 | O43: 1 | P43: 1 | Q43: 1.7
...
