Workbook

Sheet 调频测算
A1: 日期 | B1: 时点 | C1: 综合性能指标(Kp) | D1: 调节深度(MW) | E1: 中标价格元/MW | F1: 调频收入 | G1: 调频产生用电量 | H1: 用电支出 | I1: 调频产生发电量 | J1: 发电收入 | K1: 调频产生现货损益 | L1: 调频综合收入 | M1: 容量分摊费用
A2: 46169 | B2: =性能记录表格!B2 -> 9 | C2: =性能记录表格!G2 -> 1.833658 | D2: =性能记录表格!H2 -> 203.29 | E2: 5.97 | F2: =E2*D2*C2 -> 2225.4031 | G2: =调频产生发用电及损益!E10 -> -6.958 | H2: =调频产生发用电及损益!F10 -> -2600.2116 | I2: =调频产生发用电及损益!G10 -> 1.143 | J2: =调频产生发用电及损益!H10 -> 427.14024 | K2: =J2+H2 -> -2173.0713 | L2: =F2+K2+M2 -> -438.20724 | M2: =G2*70.5*容量分摊系数!B11 -> -490.539
A3: 46169 | B3: =性能记录表格!B3 -> 11 | C3: =性能记录表格!G3 -> 1.816998 | D3: =性能记录表格!H3 -> 203.51 | E3: 8 | F3: =E3*D3*C3 -> 2958.2181 | G3: =调频产生发用电及损益!E12 -> -16.03 | H3: =调频产生发用电及损益!F12 -> -5941.7279 | I3: =调频产生发用电及损益!G12 -> 18.727 | J3: =调频产生发用电及损益!H12 -> 6941.406 | K3: =J3+H3 -> 999.67811 | L3: =F3+K3+M3 -> 3844.8847 | M3: =G3*70.5*容量分摊系数!B13 -> -113.0115
A4: 46169 | B4: =性能记录表格!B4 -> 14 | C4: =性能记录表格!G4 -> 1.830384 | D4: =性能记录表格!H4 -> 182.65 | E4: 5.97 | F4: =E4*D4*C4 -> 1995.8882 | G4: =调频产生发用电及损益!E15 -> -33.207 | H4: =调频产生发用电及损益!F15 -> -11888.936 | I4: =调频产生发用电及损益!G15 -> 2.726 | J4: =调频产生发用电及损益!H15 -> 975.97615 | K4: =J4+H4 -> -10912.96 | L4: =F4+K4+M4 -> -9151.1811 | M4: =G4*70.5*容量分摊系数!B16 -> -234.10935
A5: 46169 | B5: =性能记录表格!B5 -> 18 | C5: =性能记录表格!G5 -> 1.82562 | D5: =性能记录表格!H5 -> 221.87 | E5: 5.97 | F5: =E5*D5*C5 -> 2418.1503 | G5: =调频产生发用电及损益!E19 -> -17.881 | H5: =调频产生发用电及损益!F19 -> -7469.0367 | I5: =调频产生发用电及损益!G19 -> 4.66 | J5: =调频产生发用电及损益!H19 -> 1946.5193 | K5: =J5+H5 -> -5522.5175 | L5: =F5+K5+M5 -> -5625.5881 | M5: =G5*70.5*容量分摊系数!B20 -> -2521.221
A6: 46169 | B6: =性能记录表格!B6 -> 23 | C6: =性能记录表格!G6 -> 1.84192 | D6: =性能记录表格!H6 -> 235.22 | E6: 5.97 | F6: =E6*D6*C6 -> 2586.5408 | G6: =调频产生发用电及损益!E24 -> -3.347 | H6: =调频产生发用电及损益!F24 -> -1533.2038 | I6: =调频产生发用电及损益!G24 -> 30.506 | J6: =调频产生发用电及损益!H24 -> 13974.28 | K6: =J6+H6 -> 12441.076 | L6: =F6+K6+M6 -> 14791.654 | M6: =G6*70.5*容量分摊系数!B25 -> -235.9635
A7: 均值 | B7: - | C7: =AVERAGE(C2:C6) -> 1.829716 | D7: =AVERAGE(D2:D6) -> 209.308 | E7: =AVERAGE(E2:E6) -> 6.376 | K7: =AVERAGE(K2:K6) -> -1033.5589 | M7: =AVERAGE(M2:M6) -> -718.96887
A8: 合计 | F8: =SUM(F2:F6) -> 12184.201 | G8: =SUM(G2:G6) -> -77.423 | H8: =SUM(H2:H6) -> -29433.116 | I8: =SUM(I2:I6) -> 57.762 | J8: =SUM(J2:J6) -> 24265.322 | K8: =SUM(K2:K6) -> -5167.7945 | L8: =SUM(L2:L6) -> 3421.5618 | M8: =SUM(M2:M6) -> -3594.8443
A10: 最低申报均价 | B10: =-(K7+M7)/C7/D7 -> 4.5760988

Sheet 用电结算单
A2: 德州润津储能科技有限公司(用电): | AD2: 单位：兆瓦时、元/兆瓦时、元
A3: 时段 | C3: 省内实时市场结算 | F3: 省内日前市场结算 | J3: 省内中长期结算 | N3: 跨省跨区直接交易结算 | V3: 运行成本类费用 | X3: 市场偏差类费用 | Y3: 辅助服务费用 | AA3: 虚拟电厂调节 | AB3: 总计
C4: 实时用电量 | D4: 实时市场电价 | E4: 实时电能量电费 | F4: 日前出清电量 | G4: 日前市场出清电价 | H4: 实时市场统一结算点电价 | I4: 日前电能量电费 | J4: 中长期合约电量 | K4: 中长期合约电价 | L4: 中长期结算参考点现货市场电价 | M4: 中长期合约电费 | N4: 银东双边电量 | O4: 银东双边价格 | P4: 实时市场统一结算点电价 | Q4: 银东双边电费 | R4: 银东竞价电量 | S4: 银东竞价价格 | T4: 实时市场统一结算点电价 | U4: 银东竞价电费 | V4: 运行成本补偿费用 | W4: 运行成本补偿费用分摊 | X4: 市场超额收益回收返还 | Y4: 调频辅助服务费用分摊 | Z4: 爬坡辅助服务费用分摊 | AA4: 削峰调节电量电费分摊 | AB4: 总结算电量 | AC4: 总结算均价 | AD4: 总结算费用
A5: 01:00 | C5: 0.44 | D5: 393.143 | E5: 172.98292 | F5: 0 | G5: 0 | H5: 393.143 | I5: 0 | J5: 0 | K5: 0 | L5: 0 | M5: 0 | N5: 0 | O5: 0 | P5: 393.143 | Q5: 0 | R5: 0 | S5: 0 | T5: 393.143 | U5: 0 | V5: 0 | W5: 0 | X5: 0 | Y5: 0 | Z5: 0 | AA5: 0.01 | AB5: 0.44 | AC5: 393.16573 | AD5: 172.99292
A6: 02:00 | C6: 0.44 | D6: 382.511 | E6: 168.30484 | F6: 0 | G6: 0 | H6: 382.511 | I6: 0 | J6: 0 | K6: 0 | L6: 0 | M6: 0 | N6: 0 | O6: 0 | P6: 382.511 | Q6: 0 | R6: 0 | S6: 0 | T6: 382.511 | U6: 0 | V6: 0 | W6: 0 | X6: 0 | Y6: 0 | Z6: 0 | AA6: 0.01 | AB6: 0.44 | AC6: 382.53373 | AD6: 168.31484
A7: 03:00 | C7: 0.44 | D7: 380.25 | E7: 167.31 | F7: 0 | G7: 0 | H7: 380.25 | I7: 0 | J7: 0 | K7: 0 | L7: 0 | M7: 0 | N7: 0 | O7: 0 | P7: 380.25 | Q7: 0 | R7: 0 | S7: 0 | T7: 380.25 | U7: 0 | V7: 0 | W7: 0 | X7: 0 | Y7: 0 | Z7: 0 | AA7: 0.01 | AB7: 0.44 | AC7: 380.27273 | AD7: 167.32
A8: 04:00 | C8: 3.875 | D8: 378.303 | E8: 1465.9241 | F8: 0 | G8: 0 | H8: 378.303 | I8: 0 | J8: 0 | K8: 0 | L8: 0 | M8: 0 | N8: 0 | O8: 0 | P8: 378.303 | Q8: 0 | R8: 0 | S8: 0 | T8: 378.303 | U8: 0 | V8: 0 | W8: 0 | X8: 0 | Y8: 0 | Z8: 0 | AA8: 0.07 | AB8: 3.875 | AC8: 378.32106 | AD8: 1465.9941
A9: 05:00 | C9: 4.58 | D9: 374.804 | E9: 1716.6023 | F9: 0 | G9: 0 | H9: 374.804 | I9: 0 | J9: 0 | K9: 0 | L9: 0 | M9: 0 | N9: 0 | O9: 0 | P9: 374.804 | Q9: 0 | R9: 0 | S9: 0 | T9: 374.804 | U9: 0 | V9: 0 | W9: 0 | X9: 0 | Y9: 0 | Z9: 0 | AA9: 0.08 | AB9: 4.58 | AC9: 374.82147 | AD9: 1716.6823
A10: 06:00 | C10: 0.352 | D10: 377.5 | E10: 132.88 | F10: 0 | G10: 0 | H10: 377.5 | I10: 0 | J10: 0 | K10: 0 | L10: 0 | M10: 0 | N10: 0 | O10: 0 | P10: 377.5 | Q10: 0 | R10: 0 | S10: 0 | T10: 377.5 | U10: 0 | V10: 0 | W10: 0 | X10: 0 | Y10: 0 | Z10: 0 | AA10: 0.01 | AB10: 0.352 | AC10: 377.52841 | AD10: 132.89
A11: 07:00 | C11: 1.409 | D11: 362.031 | E11: 510.10168 | F11: 0 | G11: 0 | H11: 362.031 | I11: 0 | J11: 0 | K11: 0 | L11: 0 | M11: 0 | N11: 0 | O11: 0 | P11: 362.031 | Q11: 0 | R11: 0 | S11: 0 | T11: 362.031 | U11: 0 | V11: 0 | W11: 0 | X11: 0 | Y11: 0 | Z11: 0 | AA11: 0.02 | AB11: 1.409 | AC11: 362.04519 | AD11: 510.12168
A12: 08:00 | C12: 3.523 | D12: 351.756 | E12: 1239.2364 | F12: 0 | G12: 0 | H12: 351.756 | I12: 0 | J12: 0 | K12: 0 | L12: 0 | M12: 0 | N12: 0 | O12: 0 | P12: 351.756 | Q12: 0 | R12: 0 | S12: 0 | T12: 351.756 | U12: 0 | V12: 0 | W12: 0 | X12: 0 | Y12: 0 | Z12: 0 | AA12: 0.03 | AB12: 3.523 | AC12: 351.76452 | AD12: 1239.2664
A13: 09:00 | C13: 6.958 | D13: 373.701 | E13: 2600.2116 | F13: 0 | G13: 0 | H13: 373.701 | I13: 0 | J13: 0 | K13: 0 | L13: 0 | M13: 0 | N13: 0 | O13: 0 | P13: 373.701 | Q13: 0 | R13: 0 | S13: 0 | T13: 373.701 | U13: 0 | V13: 0 | W13: 0 | X13: 0 | Y13: 0 | Z13: 0 | AA13: 0.08 | AB13: 6.958 | AC13: 373.7125 | AD13: 2600.2916
A14: 10:00 | C14: 0.44 | D14: 332.564 | E14: 146.32816 | F14: 0 | G14: 0 | H14: 332.564 | I14: 0 | J14: 0 | K14: 0 | L14: 0 | M14: 0 | N14: 0 | O14: 0 | P14: 332.564 | Q14: 0 | R14: 0 | S14: 0 | T14: 332.564 | U14: 0 | V14: 0 | W14: 0 | X14: 0 | Y14: 0 | Z14: 0 | AA14: 0.01 | AB14: 0.44 | AC14: 332.58673 | AD14: 146.33816
A15: 11:00 | C15: 16.03 | D15: 370.663 | E15: 5941.7279 | F15: 0 | G15: 0 | H15: 370.663 | I15: 0 | J15: 0 | K15: 0 | L15: 0 | M15: 0 | N15: 0 | O15: 0 | P15: 370.663 | Q15: 0 | R15: 0 | S15: 0 | T15: 370.663 | U15: 0 | V15: 0 | W15: 0 | X15: 0 | Y15: 0 | Z15: 0 | AA15: 0.5 | AB15: 16.03 | AC15: 370.69419 | AD15: 5942.2279
A16: 12:00 | C16: 0.969 | D16: 261.412 | E16: 253.30823 | F16: 0 | G16: 0 | H16: 261.412 | I16: 0 | J16: 0 | K16: 0 | L16: 0 | M16: 0 | N16: 0 | O16: 0 | P16: 261.412 | Q16: 0 | R16: 0 | S16: 0 | T16: 261.412 | U16: 0 | V16: 0 | W16: 0 | X16: 0 | Y16: 0 | Z16: 0 | AA16: 0 | AB16: 0.969 | AC16: 261.412 | AD16: 253.30823
... A23: 19:00 | C23: 0.528 | D23: 445.625 | E23: 235.29 | F23: 0 | G23: 0 | H23: 445.625 | I23: 0 | J23: 0 | K23: 0 | L23: 0 | M23: 0 | N23: 0 | O23: 0 | P23: 445.625 | Q23: 0 | R23: 0 | S23: 0 | T23: 445.625 | U23: 0 | V23: 0 | W23: 0 | X23: 0 | Y23: 0 | Z23: 0 | AA23: 0.08 | AB23: 0.528 | AC23: 445.77652 | AD23: 235.37
A24: 20:00 | C24: 0 | D24: 447.583 | E24: 0 | F24: 0 | G24: 0 | H24: 447.583 | I24: 0 | J24: 0 | K24: 0 | L24: 0 | M24: 0 | N24: 0 | O24: 0 | P24: 447.583 | Q24: 0 | R24: 0 | S24: 0 | T24: 447.583 | U24: 0 | V24: 0 | W24: 0 | X24: 0 | Y24: 0 | Z24: 0 | AA24: 0 | AB24: 0 | AC24: - | AD24: 0
A25: 21:00 | C25: 0 | D25: 451 | E25: 0 | F25: 0 | G25: 0 | H25: 451 | I25: 0 | J25: 0 | K25: 0 | L25: 0 | M25: 0 | N25: 0 | O25: 0 | P25: 451 | Q25: 0 | R25: 0 | S25: 0 | T25: 451 | U25: 0 | V25: 0 | W25: 0 | X25: 0 | Y25: 0 | Z25: 0 | AA25: 0 | AB25: 0 | AC25: - | AD25: 0
A26: 22:00 | C26: 0.264 | D26: 453 | E26: 119.592 | F26: 0 | G26: 0 | H26: 453 | I26: 0 | J26: 0 | K26: 0 | L26: 0 | M26: 0 | N26: 0 | O26: 0 | P26: 453 | Q26: 0 | R26: 0 | S26: 0 | T26: 453 | U26: 0 | V26: 0 | W26: 0 | X26: 0 | Y26: 0 | Z26: 0 | AA26: 0.04 | AB26: 0.264 | AC26: 453.15152 | AD26: 119.632
A27: 23:00 | C27: 3.347 | D27: 458.083 | E27: 1533.2038 | F27: 0 | G27: 0 | H27: 458.083 | I27: 0 | J27: 0 | K27: 0 | L27: 0 | M27: 0 | N27: 0 | O27: 0 | P27: 458.083 | Q27: 0 | R27: 0 | S27: 0 | T27: 458.083 | U27: 0 | V27: 0 | W27: 0 | X27: 0 | Y27: 0 | Z27: 0 | AA27: 0.14 | AB27: 3.347 | AC27: 458.12483 | AD27: 1533.3438
A28: 24:00 | C28: 0.352 | D28: 442.375 | E28: 155.716 | F28: 0 | G28: 0 | H28: 442.375 | I28: 0 | J28: 0 | K28: 0 | L28: 0 | M28: 0 | N28: 0 | O28: 0 | P28: 442.375 | Q28: 0 | R28: 0 | S28: 0 | T28: 442.375 | U28: 0 | V28: 0 | W28: 0 | X28: 0 | Y28: 0 | Z28: 0 | AA28: 0.01 | AB28: 0.352 | AC28: 442.40341 | AD28: 155.726
A29: 合计 | C29: =SUM(C5:C28) -> 96.447 | D29: =E29/C29 -> 377.03467 | E29: =SUM(E5:E28) -> 36363.862 | F29: 0 | G29: - | H29: - | I29: 0 | J29: 0 | K29: - | L29: - | M29: 0 | N29: 0 | O29: - | P29: - | Q29: 0 | R29: 0 | S29: - | T29: - | U29: 0 | V29: 0 | W29: 156.15 | X29: 0 | Y29: 59.46 | Z29: 0 | AA29: 1.17 | AB29: 96.447 | AC29: 379.28233 | AD29: =E29+I29+M29+W29+Y29+V29+X29+Z29+AA29 -> 36580.642

Sheet 发电结算单
A2: 德州润津储能科技有限公司(发电): | AP2: 单位：兆瓦时、元/兆瓦时、元
A3: 时段 | B3: 跨省跨区结算 | K3: 非市场结算 | N3: 调试期结算 | O3: 省内实时市场结算 | R3: 省内日前市场结算 | V3: 省内中长期结算 | Z3: 运行成本补偿及分摊 | AG3: 供热考核及返还 | AI3: 市场超额收益回收 | AJ3: 调频辅助服务 | AL3: 爬坡辅助服务 | AO3: 总结算电量及费用
B4: 省间中长期结算电量 | C4: 省间中长期结算价格 | D4: 省间中长期结算电费 | E4: 省间日前结算电量 | F4: 省间日前结算价格 | G4: 省间日前结算电费 | H4: 省间应急外送结算电量 | I4: 省间应急外送结算价格 | J4: 省间应急外送结算电费 | K4: 非市场结算电量 | L4: 非市场结算价格 | M4: 非市场电能量电费 | N4: 调试期结算电量 | O4: 实际上网电量 | P4: 实时市场节点电价 | Q4: 实时电能量电费 | R4: 日前出清电量 | S4: 日前市场出清电价 | T4: 实时市场统一结算点电价 | U4: 日前电能量电费 | V4: 中长期合约电量 | W4: 中长期合约固定价格 | X4: 中长期结算参考点现货市场电价 | Y4: 中长期合约电费 | Z4: 启动成本 | AA4: 启动方式（0冷,1温,2热） | AB4: 空载费用 | AC4: 电能量成本 | AD4: 总成本 | AE4: 运行成本补偿费用 | AF4: 运行成本分摊费用 | AG4: 供热考核费用 | AH4: 供热返还费用 | AI4: 市场超额收益回收 | AJ4: 调频辅助服务补偿费用 | AK4: 调频辅助服务分摊费用 | AL4: 爬坡辅助服务补偿费用 | AM4: 爬坡辅助服务考核费用 | AN4: 爬坡辅助服务分摊费用 | AO4: 总结算电量 | AP4: 总结算费用
A5: 00:15 | B5: 0 | C5: 0 | D5: 0 | E5: 0 | F5: 0 | G5: 0 | K5: 0 | L5: 0 | M5: 0 | N5: 0 | O5: 0 | P5: 402 | Q5: 0 | R5: 0 | S5: 0 | T5: 402 | U5: 0 | V5: 0 | W5: 0 | X5: 0 | Y5: 0 | AD5: 0 | AE5: 0 | AF5: 0 | AG5: 0 | AH5: 0 | AI5: 0 | AJ5: 0 | AK5: 0 | AL5: 0 | AM5: 0 | AN5: 0 | AO5: 0 | AP5: 0
A6: 00:30 | B6: 0 | C6: 0 | D6: 0 | E6: 0 | F6: 0 | G6: 0 | K6: 0 | L6: 0 | M6: 0 | N6: 0 | O6: 0 | P6: 392.044 | Q6: 0 | R6: 0 | S6: 0 | T6: 392.04 | U6: 0 | V6: 0 | W6: 0 | X6: 0 | Y6: 0 | AD6: 0 | AE6: 0 | AF6: 0 | AG6: 0 | AH6: 0 | AI6: 0 | AJ6: 0 | AK6: 0 | AL6: 0 | AM6: 0 | AN6: 0 | AO6: 0 | AP6: 0
A7: 00:45 | B7: 0 | C7: 0 | D7: 0 | E7: 0 | F7: 0 | G7: 0 | K7: 0 | L7: 0 | M7: 0 | N7: 0 | O7: 0 | P7: 391.027 | Q7: 0 | R7: 0 | S7: 0 | T7: 391.03 | U7: 0 | V7: 0 | W7: 0 | X7: 0 | Y7: 0 | AD7: 0 | AE7: 0 | AF7: 0 | AG7: 0 | AH7: 0 | AI7: 0 | AJ7: 0 | AK7: 0 | AL7: 0 | AM7: 0 | AN7: 0 | AO7: 0 | AP7: 0
A8: 01:00 | B8: 0 | C8: 0 | D8: 0 | E8: 0 | F8: 0 | G8: 0 | K8: 0 | L8: 0 | M8: 0 | N8: 0 | O8: 0 | P8: 387.5 | Q8: 0 | R8: 0 | S8: 0 | T8: 387.5 | U8: 0 | V8: 0 | W8: 0 | X8: 0 | Y8: 0 | AD8: 0 | AE8: 0 | AF8: 0 | AG8: 0 | AH8: 0 | AI8: 0 | AJ8: 0 | AK8: 0 | AL8: 0 | AM8: 0 | AN8: 0 | AO8: 0 | AP8: 0
A9: 01:15 | B9: 0 | C9: 0 | D9: 0 | E9: 0 | F9: 0 | G9: 0 | K9: 0 | L9: 0 | M9: 0 | N9: 0 | O9: 0 | P9: 386 | Q9: 0 | R9: 0 | S9: 0 | T9: 386 | U9: 0 | V9: 0 | W9: 0 | X9: 0 | Y9: 0 | AD9: 0 | AE9: 0 | AF9: 0 | AG9: 0 | AH9: 0 | AI9: 0 | AJ9: 0 | AK9: 0 | AL9: 0 | AM9: 0 | AN9: 0 | AO9: 0 | AP9: 0
A10: 01:30 | B10: 0 | C10: 0 | D10: 0 | E10: 0 | F10: 0 | G10: 0 | K10: 0 | L10: 0 | M10: 0 | N10: 0 | O10: 0 | P10: 383.294 | Q10: 0 | R10: 0 | S10: 0 | T10: 383.29 | U10: 0 | V10: 0 | W10: 0 | X10: 0 | Y10: 0 | AD10: 0 | AE10: 0 | AF10: 0 | AG10: 0 | AH10: 0 | AI10: 0 | AJ10: 0 | AK10: 0 | AL10: 0 | AM10: 0 | AN10: 0 | AO10: 0 | AP10: 0
A11: 01:45 | B11: 0 | C11: 0 | D11: 0 | E11: 0 | F11: 0 | G11: 0 | K11: 0 | L11: 0 | M11: 0 | N11: 0 | O11: 0 | P11: 382 | Q11: 0 | R11: 0 | S11: 0 | T11: 382 | U11: 0 | V11: 0 | W11: 0 | X11: 0 | Y11: 0 | AD11: 0 | AE11: 0 | AF11: 0 | AG11: 0 | AH11: 0 | AI11: 0 | AJ11: 0 | AK11: 0 | AL11: 0 | AM11: 0 | AN11: 0 | AO11: 0 | AP11: 0
A12: 02:00 | B12: 0 | C12: 0 | D12: 0 | E12: 0 | F12: 0 | G12: 0 | K12: 0 | L12: 0 | M12: 0 | N12: 0 | O12: 0 | P12: 378.75 | Q12: 0 | R12: 0 | S12: 0 | T12: 378.75 | U12: 0 | V12: 0 | W12: 0 | X12: 0 | Y12: 0 | AD12: 0 | AE12: 0 | AF12: 0 | AG12: 0 | AH12: 0 | AI12: 0 | AJ12: 0 | AK12: 0 | AL12: 0 | AM12: 0 | AN12: 0 | AO12: 0 | AP12: 0
A13: 02:15 | B13: 0 | C13: 0 | D13: 0 | E13: 0 | F13: 0 | G13: 0 | K13: 0 | L13: 0 | M13: 0 | N13: 0 | O13: 0 | P13: 381 | Q13: 0 | R13: 0 | S13: 0 | T13: 381 | U13: 0 | V13: 0 | W13: 0 | X13: 0 | Y13: 0 | AD13: 0 | AE13: 0 | AF13: 0 | AG13: 0 | AH13: 0 | AI13: 0 | AJ13: 0 | AK13: 0 | AL13: 0 | AM13: 0 | AN13: 0 | AO13: 0 | AP13: 0
A14: 02:30 | B14: 0 | C14: 0 | D14: 0 | E14: 0 | F14: 0 | G14: 0 | K14: 0 | L14: 0 | M14: 0 | N14: 0 | O14: 0 | P14: 380 | Q14: 0 | R14: 0 | S14: 0 | T14: 380 | U14: 0 | V14: 0 | W14: 0 | X14: 0 | Y14: 0 | AD14: 0 | AE14: 0 | AF14: 0 | AG14: 0 | AH14: 0 | AI14: 0 | AJ14: 0 | AK14: 0 | AL14: 0 | AM14: 0 | AN14: 0 | AO14: 0 | AP14: 0
A15: 02:45 | B15: 0 | C15: 0 | D15: 0 | E15: 0 | F15: 0 | G15: 0 | K15: 0 | L15: 0 | M15: 0 | N15: 0 | O15: 0 | P15: 380 | Q15: 0 | R15: 0 | S15: 0 | T15: 380 | U15: 0 | V15: 0 | W15: 0 | X15: 0 | Y15: 0 | AD15: 0 | AE15: 0 | AF15: 0 | AG15: 0 | AH15: 0 | AI15: 0 | AJ15: 0 | AK15: 0 | AL15: 0 | AM15: 0 | AN15: 0 | AO15: 0 | AP15: 0
A16: 03:00 | B16: 0 | C16: 0 | D16: 0 | E16: 0 | F16: 0 | G16: 0 | K16: 0 | L16: 0 | M16: 0 | N16: 0 | O16: 0 | P16: 380 | Q16: 0 | R16: 0 | S16: 0 | T16: 380 | U16: 0 | V16: 0 | W16: 0 | X16: 0 | Y16: 0 | AD16: 0 | AE16: 0 | AF16: 0 | AG16: 0 | AH16: 0 | AI16: 0 | AJ16: 0 | AK16: 0 | AL16: 0 | AM16: 0 | AN16: 0 | AO16: 0 | AP16: 0
... A100: 24:00 | B100: 0 | C100: 0 | D100: 0 | E100: 0 | F100: 0 | G100: 0 | K100: 0 | L100: 0 | M100: 0 | N100: 0 | O100: 0 | P100: 432.5 | Q100: 0 | R100: 0 | S100: 0 | T100: 432.5 | U100: 0 | V100: 0 | W100: 0 | X100: 0 | Y100: 0 | AD100: 0 | AE100: 0 | AF100: -0.01 | AG100: 0 | AH100: 0 | AI100: 0 | AJ100: 12184.2 | AK100: 0 | AL100: 0 | AM100: 0 | AN100: 0 | AO100: 0 | AP100: 12184.19
A101: 合计 | B101: =SUM(B5:B100) -> 0 | C101: 0 | D101: =SUM(D5:D100) -> 0 | E101: =SUM(E5:E100) -> 0 | F101: 0 | G101: =SUM(G5:G100) -> 0 | K101: =SUM(K5:K100) -> 0 | L101: =SUM(L5:L100) -> 0 | M101: =SUM(M5:M100) -> 0 | N101: =SUM(N5:N100) -> 0 | O101: =SUM(O5:O100) -> 80.36 | P101: =Q101/O101 -> 426.44213 | Q101: =SUM(Q5:Q100) -> 34268.89 | R101: 0 | S101: 0 | T101: - | U101: =SUM(U5:U100) -> 0 | V101: =SUM(V5:V100) -> 0 | W101: 0 | X101: - | Y101: =SUM(Y5:Y100) -> 0 | Z101: =SUM(Z5:Z100) -> 0 | AA101: - | AB101: =SUM(AB5:AB100) -> 0 | AC101: =SUM(AC5:AC100) -> 0 | AD101: =SUM(AD5:AD100) -> 0 | AE101: =SUM(AE5:AE100) -> 0 | AF101: =SUM(AF5:AF100) -> -0.01 | AG101: =SUM(AG5:AG100) -> 0 | AH101: =SUM(AH5:AH100) -> 0 | AI101: =SUM(AI5:AI100) -> 0 | ... AP101: =SUM(AP5:AP100) -> 46453.08

Sheet 实时出清电量
A1: 假设 | C1: 时点序号 | D1: 刻钟 | E1: 96点实时出清电量 | F1: 时点 | G1: 24点实时出清电量 | I1: 96点实际发电电量 | J1: 时点 | K1: 24点实际发电电量
A2: 1. 中标按最大值中标，如[-100,-95],按-100中标，[0,95]，按95中标 | C2: 1 | D2: 0015 | E2: 0 | F2: 1 | G2: =SUM(INDEX(E:E,(ROW()-2)*4+2):INDEX(E:E,(ROW()-2)*4+5)) -> 0 | I2: =发电结算单!AO5 -> 0 | J2: 1 | K2: =SUM(INDEX(I:I,(ROW()-2)*4+2):INDEX(I:I,(ROW()-2)*4+5)) -> 0
C3: 2 | D3: 0030 | E3: 0 | F3: 2 | G3: =SUM(INDEX(E:E,(ROW()-2)*4+2):INDEX(E:E,(ROW()-2)*4+5)) -> 0 | I3: =发电结算单!AO6 -> 0 | J3: 2 | K3: =SUM(INDEX(I:I,(ROW()-2)*4+2):INDEX(I:I,(ROW()-2)*4+5)) -> 0
C4: 3 | D4: 0045 | E4: 0 | F4: 3 | G4: =SUM(INDEX(E:E,(ROW()-2)*4+2):INDEX(E:E,(ROW()-2)*4+5)) -> 0 | I4: =发电结算单!AO7 -> 0 | J4: 3 | K4: =SUM(INDEX(I:I,(ROW()-2)*4+2):INDEX(I:I,(ROW()-2)*4+5)) -> 0
A5: 序号 | B5: 类型 | C5: 4 | D5: 0100 | E5: 0 | F5: 4 | G5: =SUM(INDEX(E:E,(ROW()-2)*4+2):INDEX(E:E,(ROW()-2)*4+5)) -> -2.84 | I5: =发电结算单!AO8 -> 0 | J5: 4 | K5: =SUM(INDEX(I:I,(ROW()-2)*4+2):INDEX(I:I,(ROW()-2)*4+5)) -> 0
A6: 1 | B6: 充电 | C6: 5 | D6: 0115 | E6: 0 | F6: 5 | G6: =SUM(INDEX(E:E,(ROW()-2)*4+2):INDEX(E:E,(ROW()-2)*4+5)) -> -3.55 | I6: =发电结算单!AO9 -> 0 | J6: 5 | K6: =SUM(INDEX(I:I,(ROW()-2)*4+2):INDEX(I:I,(ROW()-2)*4+5)) -> 0
A7: 2 | B7: 充电 | C7: 6 | D7: 0130 | E7: 0 | F7: 6 | G7: =SUM(INDEX(E:E,(ROW()-2)*4+2):INDEX(E:E,(ROW()-2)*4+5)) -> 0 | I7: =发电结算单!AO10 -> 0 | J7: 6 | K7: =SUM(INDEX(I:I,(ROW()-2)*4+2):INDEX(I:I,(ROW()-2)*4+5)) -> 0
A8: 3 | B8: 充电 | C8: 7 | D8: 0145 | E8: 0 | F8: 7 | G8: =SUM(INDEX(E:E,(ROW()-2)*4+2):INDEX(E:E,(ROW()-2)*4+5)) -> -0.9 | I8: =发电结算单!AO11 -> 0 | J8: 7 | K8: =SUM(INDEX(I:I,(ROW()-2)*4+2):INDEX(I:I,(ROW()-2)*4+5)) -> 0
A9: 4 | B9: 充电 | C9: 8 | D9: 0200 | E9: 0 | F9: 8 | G9: =SUM(INDEX(E:E,(ROW()-2)*4+2):INDEX(E:E,(ROW()-2)*4+5)) -> -2.71 | I9: =发电结算单!AO12 -> 0 | J9: 8 | K9: =SUM(INDEX(I:I,(ROW()-2)*4+2):INDEX(I:I,(ROW()-2)*4+5)) -> 0
A10: 5 | B10: 充电 | C10: 9 | D10: 0215 | E10: 0 | F10: 9 | G10: =SUM(INDEX(E:E,(ROW()-2)*4+2):INDEX(E:E,(ROW()-2)*4+5)) -> 0 | I10: =发电结算单!AO13 -> 0 | J10: 9 | K10: =SUM(INDEX(I:I,(ROW()-2)*4+2):INDEX(I:I,(ROW()-2)*4+5)) -> 1.143
A11: 6 | B11: 放电 | C11: 10 | D11: 0230 | E11: 0 | F11: 10 | G11: =SUM(INDEX(E:E,(ROW()-2)*4+2):INDEX(E:E,(ROW()-2)*4+5)) -> 0 | I11: =发电结算单!AO14 -> 0 | J11: 10 | K11: =SUM(INDEX(I:I,(ROW()-2)*4+2):INDEX(I:I,(ROW()-2)*4+5)) -> 0
A12: 7 | B12: 放电 | C12: 11 | D12: 0245 | E12: 0 | F12: 11 | G12: =SUM(INDEX(E:E,(ROW()-2)*4+2):INDEX(E:E,(ROW()-2)*4+5)) -> 0 | I12: =发电结算单!AO15 -> 0 | J12: 11 | K12: =SUM(INDEX(I:I,(ROW()-2)*4+2):INDEX(I:I,(ROW()-2)*4+5)) -> 18.727
A13: 8 | B13: 放电 | C13: 12 | D13: 0300 | E13: 0 | F13: 12 | G13: =SUM(INDEX(E:E,(ROW()-2)*4+2):INDEX(E:E,(ROW()-2)*4+5)) -> 0 | I13: =发电结算单!AO16 -> 0 | J13: 12 | K13: =SUM(INDEX(I:I,(ROW()-2)*4+2):INDEX(I:I,(ROW()-2)*4+5)) -> 0
A14: 9 | B14: 放电 | C14: 13 | D14: 0315 | E14: -0.18 | F14: 13 | G14: =SUM(INDEX(E:E,(ROW()-2)*4+2):INDEX(E:E,(ROW()-2)*4+5)) -> 0 | I14: =发电结算单!AO17 -> 0 | J14: 13 | K14: =SUM(INDEX(I:I,(ROW()-2)*4+2):INDEX(I:I,(ROW()-2)*4+5)) -> 0
A15: 10 | B15: 放电 | C15: 14 | D15: 0330 | E15: -0.35 | F15: 14 | G15: =SUM(INDEX(E:E,(ROW()-2)*4+2):INDEX(E:E,(ROW()-2)*4+5)) -> 0 | I15: =发电结算单!AO18 -> 0 | J15: 14 | K15: =SUM(INDEX(I:I,(ROW()-2)*4+2):INDEX(I:I,(ROW()-2)*4+5)) -> 2.726
C16: 15 | D16: 0345 | E16: -0.89 | F16: 15 | G16: =SUM(INDEX(E:E,(ROW()-2)*4+2):INDEX(E:E,(ROW()-2)*4+5)) -> 0 | I16: =发电结算单!AO19 -> 0 | J16: 15 | K16: =SUM(INDEX(I:I,(ROW()-2)*4+2):INDEX(I:I,(ROW()-2)*4+5)) -> 0
C17: 16 | D17: 0400 | E17: -1.42 | F17: 16 | G17: =SUM(INDEX(E:E,(ROW()-2)*4+2):INDEX(E:E,(ROW()-2)*4+5)) -> 0 | I17: =发电结算单!AO20 -> 0 | J17: 16 | K17: =SUM(INDEX(I:I,(ROW()-2)*4+2):INDEX(I:I,(ROW()-2)*4+5)) -> 0
A18: 初始电量（MWh) | B18: 0 | C18: 17 | D18: 0415 | E18: -1.42 | F18: 17 | G18: =SUM(INDEX(E:E,(ROW()-2)*4+2):INDEX(E:E,(ROW()-2)*4+5)) -> 0 | I18: =发电结算单!AO21 -> 0 | J18: 17 | K18: =SUM(INDEX(I:I,(ROW()-2)*4+2):INDEX(I:I,(ROW()-2)*4+5)) -> 0
A19: 额定装机（MW） | B19: 100 | C19: 18 | D19: 0430 | E19: -1.42 | F19: 18 | G19: =SUM(INDEX(E:E,(ROW()-2)*4+2):INDEX(E:E,(ROW()-2)*4+5)) -> 0 | I19: =发电结算单!AO22 -> 0 | J19: 18 | K19: =SUM(INDEX(I:I,(ROW()-2)*4+2):INDEX(I:I,(ROW()-2)*4+5)) -> 4.66
A20: 最大电量（MWh) | B20: 180 | C20: 19 | D20: 0445 | E20: -0.71 | F20: 19 | G20: =SUM(INDEX(E:E,(ROW()-2)*4+2):INDEX(E:E,(ROW()-2)*4+5)) -> 0 | I20: =发电结算单!AO23 -> 0 | J20: 19 | K20: =SUM(INDEX(I:I,(ROW()-2)*4+2):INDEX(I:I,(ROW()-2)*4+5)) -> 0
A21: 综合使用效率 | B21: 0.9 | C21: 20 | D21: 0500 | E21: 0 | F21: 20 | G21: =SUM(INDEX(E:E,(ROW()-2)*4+2):INDEX(E:E,(ROW()-2)*4+5)) -> 22.55 | I21: =发电结算单!AO24 -> 0 | J21: 20 | K21: =SUM(INDEX(I:I,(ROW()-2)*4+2):INDEX(I:I,(ROW()-2)*4+5)) -> 20.574
C22: 21 | D22: 0515 | E22: 0 | F22: 21 | G22: =SUM(INDEX(E:E,(ROW()-2)*4+2):INDEX(E:E,(ROW()-2)*4+5)) -> 3.04 | I22: =发电结算单!AO25 -> 0 | J22: 21 | K22: =SUM(INDEX(I:I,(ROW()-2)*4+2):INDEX(I:I,(ROW()-2)*4+5)) -> 1.496
C23: 22 | D23: 0530 | E23: 0 | F23: 22 | G23: =SUM(INDEX(E:E,(ROW()-2)*4+2):INDEX(E:E,(ROW()-2)*4+5)) -> 1.14 | I23: =发电结算单!AO26 -> 0 | J23: 22 | K23: =SUM(INDEX(I:I,(ROW()-2)*4+2):INDEX(I:I,(ROW()-2)*4+5)) -> 0.528
C24: 23 | D24: 0545 | E24: 0 | F24: 23 | G24: =SUM(INDEX(E:E,(ROW()-2)*4+2):INDEX(E:E,(ROW()-2)*4+5)) -> 0 | I24: =发电结算单!AO27 -> 0 | J24: 23 | K24: =SUM(INDEX(I:I,(ROW()-2)*4+2):INDEX(I:I,(ROW()-2)*4+5)) -> 30.506
A25: 充电电量（MWh) | B25: =SUM(#REF!)/4 -> #REF! | C25: 24 | D25: 0600 | E25: 0 | F25: 24 | G25: =SUM(INDEX(E:E,(ROW()-2)*4+2):INDEX(E:E,(ROW()-2)*4+5)) -> 0 | I25: =发电结算单!AO28 -> 0 | J25: 24 | K25: =SUM(INDEX(I:I,(ROW()-2)*4+2):INDEX(I:I,(ROW()-2)*4+5)) -> 0
A26: 充电均价(元/MWh） | B26: =B27/B25 -> #REF! | C26: 25 | D26: 0615 | E26: 0 | I26: =发电结算单!AO29 -> 0
A27: 充电费用（元,正数代表收入） | B27: =SUMPRODUCT(#REF!,#REF!)/4 -> #REF! | C27: 26 | D27: 0630 | E27: 0 | I27: =发电结算单!AO30 -> 0
A28: 充放电价差(元/MWh） | B28: =#REF!-B26 -> #REF! | C28: 27 | D28: 0645 | E28: 0 | I28: =发电结算单!AO31 -> 0
C29: 28 | D29: 0700 | E29: -0.9 | I29: =发电结算单!AO32 -> 0
C30: 29 | D30: 0715 | E30: -1.81 | I30: =发电结算单!AO33 -> 0
C31: 30 | D31: 0730 | E31: -0.9 | I31: =发电结算单!AO34 -> 0
C32: 31 | D32: 0745 | E32: 0 | I32: =发电结算单!AO35 -> 0
C33: 32 | D33: 0800 | E33: 0 | I33: =发电结算单!AO36 -> 0
A34: 序号 | B34: 类型 | C34: 33 | D34: 0815 | E34: 0 | I34: =发电结算单!AO37 -> 0.352
C35: 34 | D35: 0830 | E35: 0 | I35: =发电结算单!AO38 -> 0.791
A36: 1 | B36: 充电 | C36: 35 | D36: 0845 | E36: 0 | I36: =发电结算单!AO39 -> 0
A37: 2 | B37: 充电 | C37: 36 | D37: 0900 | E37: 0 | I37: =发电结算单!AO40 -> 0
A38: 3 | B38: 放电 | C38: 37 | D38: 0915 | E38: 0 | I38: =发电结算单!AO41 -> 0
A39: 4 | B39: 放电 | C39: 38 | D39: 0930 | E39: 0 | I39: =发电结算单!AO42 -> 0
C40: 39 | D40: 0945 | E40: 0 | I40: =发电结算单!AO43 -> 0
...

Sheet 调频产生发用电及损益
A1: =实时出清电量!F1 -> 时点 | B1: =实时出清电量!G1 -> 24点实时出清电量 | C1: =实时出清电量!K1 -> 24点实际发电电量 | D1: 计划充放状态 | E1: 调频用电量 | F1: 调频用电电费 | G1: 调频发电量 | H1: 调频发电收入
A2: =实时出清电量!F2 -> 1 | B2: =实时出清电量!G2 -> 0 | C2: =实时出清电量!K2 -> 0 | D2: =IF(B2<0,"充电",IF(B2>0,"放电","待机")) -> 待机 | E2: =-MAX(IF(OR(I2="待机",I2="放电"),用电结算单!C5,用电结算单!C5+调频产生发用电及损益!B2),0) -> -0.44 | F2: =E2*用电结算单!D5 -> -172.98292 | G2: =MAX(IF(OR(I2="待机",I2="充电"),B2,C2-B2),0) -> 0 | H2: =G2*用电结算单!D5 -> 0
A3: =实时出清电量!F3 -> 2 | B3: =实时出清电量!G3 -> 0 | C3: =实时出清电量!K3 -> 0 | D3: =IF(B3<0,"充电",IF(B3>0,"放电","待机")) -> 待机 | E3: =-MAX(IF(OR(I3="待机",I3="放电"),用电结算单!C6,用电结算单!C6+调频产生发用电及损益!B3),0) -> -0.44 | F3: =E3*用电结算单!D6 -> -168.30484 | G3: =MAX(IF(OR(I3="待机",I3="充电"),B3,C3-B3),0) -> 0 | H3: =G3*用电结算单!D6 -> 0
A4: =实时出清电量!F4 -> 3 | B4: =实时出清电量!G4 -> 0 | C4: =实时出清电量!K4 -> 0 | D4: =IF(B4<0,"充电",IF(B4>0,"放电","待机")) -> 待机 | E4: =-MAX(IF(OR(I4="待机",I4="放电"),用电结算单!C7,用电结算单!C7+调频产生发用电及损益!B4),0) -> -0.44 | F4: =E4*用电结算单!D7 -> -167.31 | G4: =MAX(IF(OR(I4="待机",I4="充电"),B4,C4-B4),0) -> 0 | H4: =G4*用电结算单!D7 -> 0
A5: =实时出清电量!F5 -> 4 | B5: =实时出清电量!G5 -> -2.84 | C5: =实时出清电量!K5 -> 0 | D5: =IF(B5<0,"充电",IF(B5>0,"放电","待机")) -> 充电 | E5: =-MAX(IF(OR(I5="待机",I5="放电"),用电结算单!C8,用电结算单!C8+调频产生发用电及损益!B5),0) -> -1.035 | F5: =E5*用电结算单!D8 -> -391.54361 | G5: =MAX(IF(OR(I5="待机",I5="充电"),B5,C5-B5),0) -> 2.84 | H5: =G5*用电结算单!D8 -> 1074.3805
A6: =实时出清电量!F6 -> 5 | B6: =实时出清电量!G6 -> -3.55 | C6: =实时出清电量!K6 -> 0 | D6: =IF(B6<0,"充电",IF(B6>0,"放电","待机")) -> 充电 | E6: =-MAX(IF(OR(I6="待机",I6="放电"),用电结算单!C9,用电结算单!C9+调频产生发用电及损益!B6),0) -> -1.03 | F6: =E6*用电结算单!D9 -> -386.04812 | G6: =MAX(IF(OR(I6="待机",I6="充电"),B6,C6-B6),0) -> 3.55 | H6: =G6*用电结算单!D9 -> 1330.5542
A7: =实时出清电量!F7 -> 6 | B7: =实时出清电量!G7 -> 0 | C7: =实时出清电量!K7 -> 0 | D7: =IF(B7<0,"充电",IF(B7>0,"放电","待机")) -> 待机 | E7: =-MAX(IF(OR(I7="待机",I7="放电"),用电结算单!C10,用电结算单!C10+调频产生发用电及损益!B7),0) -> -0.352 | F7: =E7*用电结算单!D10 -> -132.88 | G7: =MAX(IF(OR(I7="待机",I7="充电"),B7,C7-B7),0) -> 0 | H7: =G7*用电结算单!D10 -> 0
A8: =实时出清电量!F8 -> 7 | B8: =实时出清电量!G8 -> -0.9 | C8: =实时出清电量!K8 -> 0 | D8: =IF(B8<0,"充电",IF(B8>0,"放电","待机")) -> 充电 | E8: =-MAX(IF(OR(I8="待机",I8="放电"),用电结算单!C11,用电结算单!C11+调频产生发用电及损益!B8),0) -> -0.509 | F8: =E8*用电结算单!D11 -> -184.27378 | G8: =MAX(IF(OR(I8="待机",I8="充电"),B8,C8-B8),0) -> 0.9 | H8: =G8*用电结算单!D11 -> 325.8279
A9: =实时出清电量!F9 -> 8 | B9: =实时出清电量!G9 -> -2.71 | C9: =实时出清电量!K9 -> 0 | D9: =IF(B9<0,"充电",IF(B9>0,"放电","待机")) -> 充电 | E9: =-MAX(IF(OR(I9="待机",I9="放电"),用电结算单!C12,用电结算单!C12+调频产生发用电及损益!B9),0) -> -0.813 | F9: =E9*用电结算单!D12 -> -285.97763 | G9: =MAX(IF(OR(I9="待机",I9="充电"),B9,C9-B9),0) -> 2.71 | H9: =G9*用电结算单!D12 -> 953.25876
A10: =实时出清电量!F10 -> 9 | B10: =实时出清电量!G10 -> 0 | C10: =实时出清电量!K10 -> 1.143 | D10: =IF(B10<0,"充电",IF(B10>0,"放电","待机")) -> 待机 | E10: =-MAX(IF(OR(I10="待机",I10="放电"),用电结算单!C13,用电结算单!C13+调频产生发用电及损益!B10),0) -> -6.958 | F10: =E10*用电结算单!D13 -> -2600.2116 | G10: =MAX(IF(OR(I10="待机",I10="充电"),B10,C10-B10),0) -> 1.143 | H10: =G10*用电结算单!D13 -> 427.14024
A11: =实时出清电量!F11 -> 10 | B11: =实时出清电量!G11 -> 0 | C11: =实时出清电量!K11 -> 0 | D11: =IF(B11<0,"充电",IF(B11>0,"放电","待机")) -> 待机 | E11: =-MAX(IF(OR(I11="待机",I11="放电"),用电结算单!C14,用电结算单!C14+调频产生发用电及损益!B11),0) -> -0.44 | F11: =E11*用电结算单!D14 -> -146.32816 | G11: =MAX(IF(OR(I11="待机",I11="充电"),B11,C11-B11),0) -> 0 | H11: =G11*用电结算单!D14 -> 0
A12: =实时出清电量!F12 -> 11 | B12: =实时出清电量!G12 -> 0 | C12: =实时出清电量!K12 -> 18.727 | D12: =IF(B12<0,"充电",IF(B12>0,"放电","待机")) -> 待机 | E12: =-MAX(IF(OR(I12="待机",I12="放电"),用电结算单!C15,用电结算单!C15+调频产生发用电及损益!B12),0) -> -16.03 | F12: =E12*用电结算单!D15 -> -5941.7279 | G12: =MAX(IF(OR(I12="待机",I12="充电"),B12,C12-B12),0) -> 18.727 | H12: =G12*用电结算单!D15 -> 6941.406
A13: =实时出清电量!F13 -> 12 | B13: =实时出清电量!G13 -> 0 | C13: =实时出清电量!K13 -> 0 | D13: =IF(B13<0,"充电",IF(B13>0,"放电","待机")) -> 待机 | E13: =-MAX(IF(OR(I13="待机",I13="放电"),用电结算单!C16,用电结算单!C16+调频产生发用电及损益!B13),0) -> -0.969 | F13: =E13*用电结算单!D16 -> -253.30823 | G13: =MAX(IF(OR(I13="待机",I13="充电"),B13,C13-B13),0) -> 0 | H13: =G13*用电结算单!D16 -> 0
... A25: =实时出清电量!F25 -> 24 | B25: =实时出清电量!G25 -> 0 | C25: =实时出清电量!K25 -> 0 | D25: =IF(B25<0,"充电",IF(B25>0,"放电","待机")) -> 待机 | E25: =-MAX(IF(OR(I25="待机",I25="放电"),用电结算单!C28,用电结算单!C28+调频产生发用电及损益!B25),0) -> -0.352 | F25: =E25*用电结算单!D28 -> -155.716 | G25: =MAX(IF(OR(I25="待机",I25="充电"),B25,C25-B25),0) -> 0 | H25: =G25*用电结算单!D28 -> 0

Sheet 性能记录表格
A1: 日期 | B1: 小时 | C1: 电站名称 | D1: AGC K1 | E1: AGC K2 | F1: AGC K3 | G1: 综合性能指标(Kp) | H1: 调节深度(MW)
A2: 2026-05-27 | B2: 9 | C2: 苏留润津储能 | D2: 1.3 | E2: 1.766441 | F2: 1.585311 | G2: 1.833658 | H2: 203.29
A3: 2026-05-27 | B3: 11 | C3: 苏留润津储能 | D3: 1.3 | E3: 1.74537 | F3: 1.554321 | G3: 1.816998 | H3: 203.51
A4: 2026-05-27 | B4: 14 | C4: 苏留润津储能 | D4: 1.3 | E4: 1.740784 | F4: 1.613072 | G4: 1.830384 | H4: 182.65
A5: 2026-05-27 | B5: 18 | C5: 苏留润津储能 | D5: 1.3 | E5: 1.742903 | F5: 1.591398 | G5: 1.82562 | H5: 221.87
A6: 2026-05-27 | B6: 23 | C6: 苏留润津储能 | D6: 1.3 | E6: 1.784839 | F6: 1.588172 | G6: 1.84192 | H6: 235.22

Sheet 容量分摊系数
A1: 时点 | B1: 当前月份
B2: 5月
A3: 1 | B3: 1
A4: 2 | B4: 1
A5: 3 | B5: 1
A6: 4 | B6: 1
A7: 5 | B7: 1
A8: 6 | B8: 1
A9: 7 | B9: 1
A10: 8 | B10: 1
A11: 9 | B11: 1
A12: 10 | B12: 0.3
A13: 11 | B13: 0.1
A14: 12 | B14: 0.1
... A26: 24 | B26: 1
