Workbook

Sheet 充放测算
A1: 储能每日充放测算
A2: 充电支出 | L2: 放电收入 | O2: 现货收益 | P2: 其他
A3: 充电均价 (元/MWh) | B3: 充电电量(MWh) | C3: 交易充电 费用(元) | D3: 优发优购(元) | E3: 上网线损(元) | F3: 输配电费(元) | G3: 政府基金(元) | H3: 系统运行(元) | I3: 容量分摊(元) | J3: 容量分摊 系数 | K3: 充电总 费用(元) | L3: 放电均价 (元/MWh) | M3: 放电电量(MWh) | N3: 放电电费 (元) | O3: （元） | P3: 综合效率 | Q3: 充放价差 (元/MWh)
A4: =充电日清算费用!AA29 -> -70.566573 | B4: =-充电日清算费用!Z29 -> -193.51 | C4: =-充电日清算费用!AB29 -> 13655.338 | D4: =$B$4*I12 -> -677.285 | E4: =$B$4*I13 -> -638.583 | F4: =B4*(1-P4)*I8 -> -6056.364 | G4: =B4*(1-P4)*I9 -> -857.42208 | H4: =$B$4*I14 -> 561.179 | I4: =B4*J4*70.5 -> -1585.9062 | J4: 0.11624786 | K4: =C4+D4+E4+F4+G4+H4+I4 -> 4400.9563 | L4: =放电日清算费用!P101 -> 615.33889 | M4: =放电日清算费用!AJ101 -> 161.95 | N4: =放电日清算费用!AK101 -> 99652.853 | O4: =N4+K4 -> 104053.81 | P4: =-M4/B4 -> 0.83690765 | Q4: =L4-A4 -> 685.90546
A6: 说明 | B6: 根据预测电价，输入充电均价，放电均价。根据充电时段计算出对于的容量分摊系数，计入容量分摊。 | K6: =K3 -> 充电总 费用(元) | N6: 清分单收益 | O6: =N4+C4 -> 113308.19
A7: 1 | B7: 充电均价（元 / MWh）输入限制：-100 至 800； | K7: =C3 -> 交易充电 费用(元) | N7: 调频收益 | O7: =放电日清算费用!AE101 -> 0
A8: 2 | B8: 输配电价（元 / MWh）设置：收取损耗部分输配电价； | I8: 191.9 | J8: 政府核定 | K8: =D3 -> 优发优购(元) | N8: 价差收益 | O8: =O6-O7 -> 113308.19
A9: 3 | B9: 政府基金（元 /M Wh）设置：收取损耗部分输配电价； | I9: 27.168 | J9: 政府核定 | K9: =E3 -> 上网线损(元)
A10: 4 | B10: 综合效率设置：60% 至 100%； | K10: =F3 -> 输配电费(元)
A11: 5 | B11: 放电均价（元 / MWh）输入限制：100 至 1500； | K11: =G3 -> 政府基金(元)
A12: 6 | B12: 优发优购曲线匹配偏差标准：暂以上月替代； | I12: 3.5 | J12: 上月均值 | K12: =H3 -> 系统运行(元)
A13: 7 | B13: 上网环节线损费用； | I13: 3.3 | J13: 上月均值 | K13: =I3 -> 容量分摊(元)
A14: 8 | B14: 系统运行费用； | I14: -2.9 | J14: 上月均值
A15: 9 | B15: 容量分摊：按季度分为4种类型，详见附表；
A16: 10 | B16: 根据选择的充电时段，计算容量分摊系数。

Sheet 充电日清算费用
F1: 2026年5月21日日清算临时结果单（售电侧）
A2: 德州润津储能科技有限公司(用电): | AB2: 单位：兆瓦时、元/兆瓦时、元
A3: 时段 | C3: 省内实时市场结算 | F3: 省内日前市场结算 | J3: 省内中长期结算 | N3: 跨省跨区直接交易结算 | V3: 运行成本类费用 | X3: 市场偏差类费用 | Y3: 辅助服务费用 | Z3: 总计
C4: 实时用电量 | D4: 实时市场电价 | E4: 实时电能量电费 | F4: 日前出清电量 | G4: 日前市场出清电价 | H4: 实时市场统一结算点电价 | I4: 日前电能量电费 | J4: 中长期合约电量 | K4: 中长期合约电价 | L4: 中长期结算参考点现货市场电价 | M4: 中长期合约电费 | N4: 银东双边电量 | O4: 银东双边价格 | P4: 实时市场统一结算点电价 | Q4: 银东双边电费 | R4: 银东竞价电量 | S4: 银东竞价价格 | T4: 实时市场统一结算点电价 | U4: 银东竞价电费 | V4: 运行成本补偿费用 | W4: 运行成本补偿费用分摊 | X4: 市场超额收益回收返还 | Y4: 调频辅助服务费用分摊 | Z4: 总结算电量 | AA4: 总结算均价 | AB4: 总结算费用
A5: 01:00 | C5: 0.264 | D5: 442.722 | E5: 116.87861 | F5: 0 | G5: 0 | H5: 442.722 | I5: 0 | J5: 0 | K5: 0 | L5: 0 | M5: 0 | N5: 0 | O5: 0 | P5: 442.722 | Q5: 0 | R5: 0 | S5: 0 | T5: 442.722 | U5: 0 | V5: 0 | W5: 0 | X5: 0 | Y5: 0 | Z5: 0.264 | AA5: 442.722 | AB5: 116.87861
A6: 02:00 | C6: 0.264 | D6: 413.02 | E6: 109.03728 | F6: 0 | G6: 0 | H6: 413.02 | I6: 0 | J6: 0 | K6: 0 | L6: 0 | M6: 0 | N6: 0 | O6: 0 | P6: 413.02 | Q6: 0 | R6: 0 | S6: 0 | T6: 413.02 | U6: 0 | V6: 0 | W6: 0 | X6: 0 | Y6: 0 | Z6: 0.264 | AA6: 413.02 | AB6: 109.03728
A7: 03:00 | C7: 0.352 | D7: 392.87 | E7: 138.29024 | F7: 0 | G7: 0 | H7: 392.87 | I7: 0 | J7: 0 | K7: 0 | L7: 0 | M7: 0 | N7: 0 | O7: 0 | P7: 392.87 | Q7: 0 | R7: 0 | S7: 0 | T7: 392.87 | U7: 0 | V7: 0 | W7: 0 | X7: 0 | Y7: 0 | Z7: 0.352 | AA7: 392.87 | AB7: 138.29024
A8: 04:00 | C8: 0.264 | D8: 374.35 | E8: 98.8284 | F8: 0 | G8: 0 | H8: 374.35 | I8: 0 | J8: 0 | K8: 0 | L8: 0 | M8: 0 | N8: 0 | O8: 0 | P8: 374.35 | Q8: 0 | R8: 0 | S8: 0 | T8: 374.35 | U8: 0 | V8: 0 | W8: 0 | X8: 0 | Y8: 0 | Z8: 0.264 | AA8: 374.35 | AB8: 98.8284
A9: 05:00 | C9: 0.264 | D9: 391.84 | E9: 103.44576 | F9: 0 | G9: 0 | H9: 391.84 | I9: 0 | J9: 0 | K9: 0 | L9: 0 | M9: 0 | N9: 0 | O9: 0 | P9: 391.84 | Q9: 0 | R9: 0 | S9: 0 | T9: 391.84 | U9: 0 | V9: 0 | W9: 0 | X9: 0 | Y9: 0 | Z9: 0.264 | AA9: 391.84 | AB9: 103.44576
A10: 06:00 | C10: 0.264 | D10: 392.15 | E10: 103.5276 | F10: 0 | G10: 0 | H10: 392.15 | I10: 0 | J10: 0 | K10: 0 | L10: 0 | M10: 0 | N10: 0 | O10: 0 | P10: 392.15 | Q10: 0 | R10: 0 | S10: 0 | T10: 392.15 | U10: 0 | V10: 0 | W10: 0 | X10: 0 | Y10: 0 | Z10: 0.264 | AA10: 392.15 | AB10: 103.5276
A11: 07:00 | C11: 0.352 | D11: 350 | E11: 123.2 | F11: 0 | G11: 0 | H11: 350 | I11: 0 | J11: 0 | K11: 0 | L11: 0 | M11: 0 | N11: 0 | O11: 0 | P11: 350 | Q11: 0 | R11: 0 | S11: 0 | T11: 350 | U11: 0 | V11: 0 | W11: 0 | X11: 0 | Y11: 0 | Z11: 0.352 | AA11: 350 | AB11: 123.2
A12: 08:00 | C12: 0.264 | D12: -80 | E12: -21.12 | F12: 0 | G12: 0 | H12: -80 | I12: 0 | J12: 0 | K12: 0 | L12: 0 | M12: 0 | N12: 0 | O12: 0 | P12: -80 | Q12: 0 | R12: 0 | S12: 0 | T12: -80 | U12: 0 | V12: 0 | W12: 0 | X12: 0 | Y12: 0 | Z12: 0.264 | AA12: -80 | AB12: -21.12
A13: 09:00 | C13: 0.352 | D13: -80 | E13: -28.16 | F13: 0 | G13: 0 | H13: -80 | I13: 0 | J13: 0 | K13: 0 | L13: 0 | M13: 0 | N13: 0 | O13: 0 | P13: -80 | Q13: 0 | R13: 0 | S13: 0 | T13: -80 | U13: 0 | V13: 0 | W13: 0 | X13: 0 | Y13: 0 | Z13: 0.352 | AA13: -80 | AB13: -28.16
A14: 10:00 | C14: 0.352 | D14: -80 | E14: -28.16 | F14: 0 | G14: 0 | H14: -80 | I14: 0 | J14: 0 | K14: 0 | L14: 0 | M14: 0 | N14: 0 | O14: 0 | P14: -80 | Q14: 0 | R14: 0 | S14: 0 | T14: -80 | U14: 0 | V14: 0 | W14: 0 | X14: 0 | Y14: 0 | Z14: 0.352 | AA14: -80 | AB14: -28.16
A15: 11:00 | C15: 8.807 | D15: -80 | E15: -704.56 | F15: 0 | G15: 0 | H15: -80 | I15: 0 | J15: 0 | K15: 0 | L15: 0 | M15: 0 | N15: 0 | O15: 0 | P15: -80 | Q15: 0 | R15: 0 | S15: 0 | T15: -80 | U15: 0 | V15: 0 | W15: 0 | X15: 0 | Y15: 0 | Z15: 8.807 | AA15: -80 | AB15: -704.56
A16: 12:00 | C16: 81.562 | D16: -80 | E16: -6524.96 | F16: 0 | G16: 0 | H16: -80 | I16: 0 | J16: 0 | K16: 0 | L16: 0 | M16: 0 | N16: 0 | O16: 0 | P16: -80 | Q16: 0 | R16: 0 | S16: 0 | T16: -80 | U16: 0 | V16: 0 | W16: 0 | X16: 0 | Y16: 0 | Z16: 81.562 | AA16: -80 | AB16: -6524.96
... A24: 20:00 | C24: 0.088 | D24: 606.714 | E24: 53.390832 | F24: 0 | G24: 0 | H24: 606.714 | I24: 0 | J24: 0 | K24: 0 | L24: 0 | M24: 0 | N24: 0 | O24: 0 | P24: 606.714 | Q24: 0 | R24: 0 | S24: 0 | T24: 606.714 | U24: 0 | V24: 0 | W24: 0 | X24: 0 | Y24: 0 | Z24: 0.088 | AA24: 606.714 | AB24: 53.390832
A25: 21:00 | C25: 0 | D25: 609.75 | E25: 0 | F25: 0 | G25: 0 | H25: 609.75 | I25: 0 | J25: 0 | K25: 0 | L25: 0 | M25: 0 | N25: 0 | O25: 0 | P25: 609.75 | Q25: 0 | R25: 0 | S25: 0 | T25: 609.75 | U25: 0 | V25: 0 | W25: 0 | X25: 0 | Y25: 0 | Z25: 0 | AA25: - | AB25: 0
A26: 22:00 | C26: 0 | D26: 619.107 | E26: 0 | F26: 0 | G26: 0 | H26: 619.107 | I26: 0 | J26: 0 | K26: 0 | L26: 0 | M26: 0 | N26: 0 | O26: 0 | P26: 619.107 | Q26: 0 | R26: 0 | S26: 0 | T26: 619.107 | U26: 0 | V26: 0 | W26: 0 | X26: 0 | Y26: 0 | Z26: 0 | AA26: - | AB26: 0
A27: 23:00 | C27: 0 | D27: 617.57 | E27: 0 | F27: 0 | G27: 0 | H27: 617.57 | I27: 0 | J27: 0 | K27: 0 | L27: 0 | M27: 0 | N27: 0 | O27: 0 | P27: 617.57 | Q27: 0 | R27: 0 | S27: 0 | T27: 617.57 | U27: 0 | V27: 0 | W27: 0 | X27: 0 | Y27: 0 | Z27: 0 | AA27: - | AB27: 0
A28: 24:00 | C28: 0.176 | D28: 612 | E28: 107.712 | F28: 0 | G28: 0 | H28: 612 | I28: 0 | J28: 0 | K28: 0 | L28: 0 | M28: 0 | N28: 0 | O28: 0 | P28: 612 | Q28: 0 | R28: 0 | S28: 0 | T28: 612 | U28: 0 | V28: 0 | W28: 0 | X28: 0 | Y28: 0 | Z28: 0.176 | AA28: 612 | AB28: 107.712
A29: 合计 | C29: 193.51 | D29: -71.286588 | E29: -13794.668 | F29: 0 | G29: - | H29: - | I29: 0 | J29: 0 | K29: - | L29: - | M29: 0 | N29: 0 | O29: - | P29: - | Q29: 0 | R29: 0 | S29: - | T29: - | U29: 0 | V29: 0 | W29: 139.33 | X29: 0 | Y29: 0 | Z29: 193.51 | AA29: -70.566573 | AB29: -13655.338

Sheet 放电日清算费用
A1: 2026年5月21日日清算临时结果单（发电侧）
A2: 德州润津储能科技有限公司(发电): | AK2: 单位：兆瓦时、元/兆瓦时、元
A3: 时段 | B3: 跨省跨区结算 | K3: 非市场结算 | N3: 调试期结算 | O3: 省内实时市场结算 | R3: 省内日前市场结算 | V3: 省内中长期结算 | Z3: 运行成本补偿及分摊 | AB3: 供热考核及返还 | AD3: 市场超额收益回收 | AE3: 调频辅助服务 | AG3: 爬坡辅助服务 | AJ3: 总结算电量及费用
B4: 省间中长期结算电量 | C4: 省间中长期结算价格 | D4: 省间中长期结算电费 | E4: 省间日前结算电量 | F4: 省间日前结算价格 | G4: 省间日前结算电费 | H4: 省间应急外送结算电量 | I4: 省间应急外送结算价格 | J4: 省间应急外送结算电费 | K4: 非市场结算电量 | L4: 非市场结算价格 | M4: 非市场电能量电费 | N4: 调试期结算电量 | O4: 实际上网电量 | P4: 实时市场节点电价 | Q4: 实时电能量电费 | R4: 日前出清电量 | S4: 日前市场出清电价 | T4: 实时市场统一结算点电价 | U4: 日前电能量电费 | V4: 中长期合约电量 | W4: 中长期合约固定价格 | X4: 中长期结算参考点现货市场电价 | Y4: 中长期合约电费 | Z4: 运行成本补偿费用 | AA4: 运行成本分摊费用 | AB4: 供热考核费用 | AC4: 供热返还费用 | AD4: 市场超额收益回收 | AE4: 调频辅助服务补偿费用 | AF4: 调频辅助服务分摊费用 | AG4: 爬坡辅助服务补偿费用 | AH4: 爬坡辅助服务考核费用 | AI4: 爬坡辅助服务分摊费用 | AJ4: 总结算电量 | AK4: 总结算费用
A5: 00:15 | B5: 0 | C5: 0 | D5: 0 | E5: 0 | F5: 0 | G5: 0 | K5: 0 | L5: 0 | M5: 0 | N5: 0 | O5: 0 | P5: 438.889 | Q5: 0 | R5: 0 | S5: 0 | T5: 438.89 | U5: 0 | V5: 0 | W5: 0 | X5: 0 | Y5: 0 | Z5: 0 | AA5: 0 | AB5: 0 | AC5: 0 | AD5: 0 | AE5: 0 | AF5: 0 | AG5: 0 | AH5: 0 | AI5: 0 | AJ5: 0 | AK5: 0
A6: 00:30 | B6: 0 | C6: 0 | D6: 0 | E6: 0 | F6: 0 | G6: 0 | K6: 0 | L6: 0 | M6: 0 | N6: 0 | O6: 0 | P6: 437.6 | Q6: 0 | R6: 0 | S6: 0 | T6: 437.6 | U6: 0 | V6: 0 | W6: 0 | X6: 0 | Y6: 0 | Z6: 0 | AA6: 0 | AB6: 0 | AC6: 0 | AD6: 0 | AE6: 0 | AF6: 0 | AG6: 0 | AH6: 0 | AI6: 0 | AJ6: 0 | AK6: 0
A7: 00:45 | B7: 0 | C7: 0 | D7: 0 | E7: 0 | F7: 0 | G7: 0 | K7: 0 | L7: 0 | M7: 0 | N7: 0 | O7: 0 | P7: 462.4 | Q7: 0 | R7: 0 | S7: 0 | T7: 462.4 | U7: 0 | V7: 0 | W7: 0 | X7: 0 | Y7: 0 | Z7: 0 | AA7: 0 | AB7: 0 | AC7: 0 | AD7: 0 | AE7: 0 | AF7: 0 | AG7: 0 | AH7: 0 | AI7: 0 | AJ7: 0 | AK7: 0
A8: 01:00 | B8: 0 | C8: 0 | D8: 0 | E8: 0 | F8: 0 | G8: 0 | K8: 0 | L8: 0 | M8: 0 | N8: 0 | O8: 0 | P8: 432 | Q8: 0 | R8: 0 | S8: 0 | T8: 432 | U8: 0 | V8: 0 | W8: 0 | X8: 0 | Y8: 0 | Z8: 0 | AA8: 0 | AB8: 0 | AC8: 0 | AD8: 0 | AE8: 0 | AF8: 0 | AG8: 0 | AH8: 0 | AI8: 0 | AJ8: 0 | AK8: 0
A9: 01:15 | B9: 0 | C9: 0 | D9: 0 | E9: 0 | F9: 0 | G9: 0 | K9: 0 | L9: 0 | M9: 0 | N9: 0 | O9: 0 | P9: 428 | Q9: 0 | R9: 0 | S9: 0 | T9: 428 | U9: 0 | V9: 0 | W9: 0 | X9: 0 | Y9: 0 | Z9: 0 | AA9: 0 | AB9: 0 | AC9: 0 | AD9: 0 | AE9: 0 | AF9: 0 | AG9: 0 | AH9: 0 | AI9: 0 | AJ9: 0 | AK9: 0
A10: 01:30 | B10: 0 | C10: 0 | D10: 0 | E10: 0 | F10: 0 | G10: 0 | K10: 0 | L10: 0 | M10: 0 | N10: 0 | O10: 0 | P10: 409.4 | Q10: 0 | R10: 0 | S10: 0 | T10: 409.4 | U10: 0 | V10: 0 | W10: 0 | X10: 0 | Y10: 0 | Z10: 0 | AA10: 0 | AB10: 0 | AC10: 0 | AD10: 0 | AE10: 0 | AF10: 0 | AG10: 0 | AH10: 0 | AI10: 0 | AJ10: 0 | AK10: 0
A11: 01:45 | B11: 0 | C11: 0 | D11: 0 | E11: 0 | F11: 0 | G11: 0 | K11: 0 | L11: 0 | M11: 0 | N11: 0 | O11: 0 | P11: 413.28 | Q11: 0 | R11: 0 | S11: 0 | T11: 413.28 | U11: 0 | V11: 0 | W11: 0 | X11: 0 | Y11: 0 | Z11: 0 | AA11: 0 | AB11: 0 | AC11: 0 | AD11: 0 | AE11: 0 | AF11: 0 | AG11: 0 | AH11: 0 | AI11: 0 | AJ11: 0 | AK11: 0
A12: 02:00 | B12: 0 | C12: 0 | D12: 0 | E12: 0 | F12: 0 | G12: 0 | K12: 0 | L12: 0 | M12: 0 | N12: 0 | O12: 0 | P12: 401.4 | Q12: 0 | R12: 0 | S12: 0 | T12: 401.4 | U12: 0 | V12: 0 | W12: 0 | X12: 0 | Y12: 0 | Z12: 0 | AA12: 0 | AB12: 0 | AC12: 0 | AD12: 0 | AE12: 0 | AF12: 0 | AG12: 0 | AH12: 0 | AI12: 0 | AJ12: 0 | AK12: 0
A13: 02:15 | B13: 0 | C13: 0 | D13: 0 | E13: 0 | F13: 0 | G13: 0 | K13: 0 | L13: 0 | M13: 0 | N13: 0 | O13: 0 | P13: 402 | Q13: 0 | R13: 0 | S13: 0 | T13: 402 | U13: 0 | V13: 0 | W13: 0 | X13: 0 | Y13: 0 | Z13: 0 | AA13: 0 | AB13: 0 | AC13: 0 | AD13: 0 | AE13: 0 | AF13: 0 | AG13: 0 | AH13: 0 | AI13: 0 | AJ13: 0 | AK13: 0
A14: 02:30 | B14: 0 | C14: 0 | D14: 0 | E14: 0 | F14: 0 | G14: 0 | K14: 0 | L14: 0 | M14: 0 | N14: 0 | O14: 0 | P14: 395.08 | Q14: 0 | R14: 0 | S14: 0 | T14: 395.08 | U14: 0 | V14: 0 | W14: 0 | X14: 0 | Y14: 0 | Z14: 0 | AA14: 0 | AB14: 0 | AC14: 0 | AD14: 0 | AE14: 0 | AF14: 0 | AG14: 0 | AH14: 0 | AI14: 0 | AJ14: 0 | AK14: 0
A15: 02:45 | B15: 0 | C15: 0 | D15: 0 | E15: 0 | F15: 0 | G15: 0 | K15: 0 | L15: 0 | M15: 0 | N15: 0 | O15: 0 | P15: 392 | Q15: 0 | R15: 0 | S15: 0 | T15: 392 | U15: 0 | V15: 0 | W15: 0 | X15: 0 | Y15: 0 | Z15: 0 | AA15: 0 | AB15: 0 | AC15: 0 | AD15: 0 | AE15: 0 | AF15: 0 | AG15: 0 | AH15: 0 | AI15: 0 | AJ15: 0 | AK15: 0
A16: 03:00 | B16: 0 | C16: 0 | D16: 0 | E16: 0 | F16: 0 | G16: 0 | K16: 0 | L16: 0 | M16: 0 | N16: 0 | O16: 0 | P16: 382.4 | Q16: 0 | R16: 0 | S16: 0 | T16: 382.4 | U16: 0 | V16: 0 | W16: 0 | X16: 0 | Y16: 0 | Z16: 0 | AA16: 0 | AB16: 0 | AC16: 0 | AD16: 0 | AE16: 0 | AF16: 0 | AG16: 0 | AH16: 0 | AI16: 0 | AJ16: 0 | AK16: 0
... A100: 24:00 | B100: 0 | C100: 0 | D100: 0 | E100: 0 | F100: 0 | G100: 0 | K100: 0 | L100: 0 | M100: 0 | N100: 0 | O100: 0 | P100: 597 | Q100: 0 | R100: 0 | S100: 0 | T100: 597 | U100: 0 | V100: 0 | W100: 0 | X100: 0 | Y100: 0 | Z100: 0 | AA100: -1.28 | AB100: 0 | AC100: 0 | AD100: 0 | AE100: 0 | AF100: 0 | AG100: 0 | AH100: 0 | AI100: 0 | AJ100: 0 | AK100: -1.28
A101: 合计 | B101: 0 | C101: 0 | D101: 0 | E101: 0 | F101: 0 | G101: 0 | K101: 0 | L101: 0 | M101: 0 | N101: 0 | O101: 161.95 | P101: 615.33889 | Q101: 99654.133 | R101: 0 | S101: 0 | T101: - | U101: 0 | V101: 0 | W101: 0 | X101: - | Y101: 0 | Z101: 0 | AA101: -1.28 | AB101: 0 | AC101: 0 | AD101: 0 | AE101: 0 | AF101: 0 | AG101: 0 | AH101: 0 | AI101: 0 | AJ101: 161.95 | AK101: 99652.853

Sheet 报价及预中标
A1: 假设 | G1: 时点序号 | I1: 时点 | J1: 统一结算日前 | K1: 节点日前电价 | L1: 真实充电中标 | M1: 真实放电中标 | N1: 充放电曲线
A2: 1. 中标按最大值中标，如[-100,-95],按-100中标，[0,95]，按95中标 | G2: 1 | H2: 20250922 0015 | I2: =RIGHT(H2,4) -> 0015 | J2: 438.889 | K2: 438.889 | L2: =IF(N2<=0, N2, 0) -> -0.05 | M2: =IF(N2>=0, N2, 0) -> 0 | N2: -0.05
G3: 2 | H3: 20250922 0030 | I3: =RIGHT(H3,4) -> 0030 | J3: 437.6 | K3: 437.6 | L3: =IF(N3<=0, N3, 0) -> 0 | M3: =IF(N3>=0, N3, 0) -> 0 | N3: 0
G4: 3 | H4: 20250922 0045 | I4: =RIGHT(H4,4) -> 0045 | J4: 462.4 | K4: 462.4 | L4: =IF(N4<=0, N4, 0) -> 0 | M4: =IF(N4>=0, N4, 0) -> 0 | N4: 0
A5: 序号 | B5: 类型 | C5: 开始出力（MW） | D5: 结束出力（MW） | E5: 报价（元/MWh） | G5: 4 | H5: 20250922 0100 | I5: =RIGHT(H5,4) -> 0100 | J5: 432 | K5: 432 | L5: =IF(N5<=0, N5, 0) -> 0 | M5: =IF(N5>=0, N5, 0) -> 0 | N5: 0
A6: 1 | B6: 充电 | C6: -100 | D6: -95 | E6: 0 | G6: 5 | H6: 20250922 0115 | I6: =RIGHT(H6,4) -> 0115 | J6: 428 | K6: 428 | L6: =IF(N6<=0, N6, 0) -> 0 | M6: =IF(N6>=0, N6, 0) -> 0 | N6: 0
A7: 2 | B7: 充电 | C7: -95 | D7: 0 | E7: 100 | G7: 6 | H7: 20250922 0130 | I7: =RIGHT(H7,4) -> 0130 | J7: 409.4 | K7: 409.4 | L7: =IF(N7<=0, N7, 0) -> 0 | M7: =IF(N7>=0, N7, 0) -> 0 | N7: 0
A8: 3 | B8: 充电 | G8: 7 | H8: 20250922 0145 | I8: =RIGHT(H8,4) -> 0145 | J8: 413.28 | K8: 413.28 | L8: =IF(N8<=0, N8, 0) -> 0 | M8: =IF(N8>=0, N8, 0) -> 0 | N8: 0
A9: 4 | B9: 充电 | G9: 8 | H9: 20250922 0200 | I9: =RIGHT(H9,4) -> 0200 | J9: 401.4 | K9: 401.4 | L9: =IF(N9<=0, N9, 0) -> 0 | M9: =IF(N9>=0, N9, 0) -> 0 | N9: 0
A10: 5 | B10: 充电 | G10: 9 | H10: 20250922 0215 | I10: =RIGHT(H10,4) -> 0215 | J10: 402 | K10: 402 | L10: =IF(N10<=0, N10, 0) -> 0 | M10: =IF(N10>=0, N10, 0) -> 0 | N10: 0
A11: 6 | B11: 放电 | C11: 0 | D11: 95 | E11: 250 | G11: 10 | H11: 20250922 0230 | I11: =RIGHT(H11,4) -> 0230 | J11: 395.08 | K11: 395.08 | L11: =IF(N11<=0, N11, 0) -> 0 | M11: =IF(N11>=0, N11, 0) -> 0 | N11: 0
A12: 7 | B12: 放电 | C12: 95 | D12: 100 | E12: 300 | G12: 11 | H12: 20250922 0245 | I12: =RIGHT(H12,4) -> 0245 | J12: 392 | K12: 392 | L12: =IF(N12<=0, N12, 0) -> 0 | M12: =IF(N12>=0, N12, 0) -> 0 | N12: 0
A13: 8 | B13: 放电 | G13: 12 | H13: 20250922 0300 | I13: =RIGHT(H13,4) -> 0300 | J13: 382.4 | K13: 382.4 | L13: =IF(N13<=0, N13, 0) -> 0 | M13: =IF(N13>=0, N13, 0) -> 0 | N13: 0
A14: 9 | B14: 放电 | G14: 13 | H14: 20250922 0315 | I14: =RIGHT(H14,4) -> 0315 | J14: 373.52 | K14: 373.52 | L14: =IF(N14<=0, N14, 0) -> 0 | M14: =IF(N14>=0, N14, 0) -> 0 | N14: 0
A15: 10 | B15: 放电 | G15: 14 | H15: 20250922 0330 | I15: =RIGHT(H15,4) -> 0330 | J15: 374 | K15: 374 | L15: =IF(N15<=0, N15, 0) -> 0 | M15: =IF(N15>=0, N15, 0) -> 0 | N15: 0
G16: 15 | H16: 20250922 0345 | I16: =RIGHT(H16,4) -> 0345 | J16: 373.88 | K16: 373.88 | L16: =IF(N16<=0, N16, 0) -> 0 | M16: =IF(N16>=0, N16, 0) -> 0 | N16: 0
G17: 16 | H17: 20250922 0400 | I17: =RIGHT(H17,4) -> 0400 | J17: 376 | K17: 376 | L17: =IF(N17<=0, N17, 0) -> 0 | M17: =IF(N17>=0, N17, 0) -> 0 | N17: 0
A18: 初始电量（MWh) | B18: 0 | G18: 17 | H18: 20250922 0415 | I18: =RIGHT(H18,4) -> 0415 | J18: 376 | K18: 376 | L18: =IF(N18<=0, N18, 0) -> 0 | M18: =IF(N18>=0, N18, 0) -> 0 | N18: 0
A19: 额定装机（MW） | B19: 100 | G19: 18 | H19: 20250922 0430 | I19: =RIGHT(H19,4) -> 0430 | J19: 385.36 | K19: 385.36 | L19: =IF(N19<=0, N19, 0) -> 0 | M19: =IF(N19>=0, N19, 0) -> 0 | N19: 0
A20: 最大电量（MWh) | B20: 180 | G20: 19 | H20: 20250922 0445 | I20: =RIGHT(H20,4) -> 0445 | J20: 398 | K20: 398 | L20: =IF(N20<=0, N20, 0) -> 0 | M20: =IF(N20>=0, N20, 0) -> 0 | N20: 0
A21: 综合使用效率 | B21: 0.9 | G21: 20 | H21: 20250922 0500 | I21: =RIGHT(H21,4) -> 0500 | J21: 408 | K21: 408 | L21: =IF(N21<=0, N21, 0) -> 0 | M21: =IF(N21>=0, N21, 0) -> 0 | N21: 0
G22: 21 | H22: 20250922 0515 | I22: =RIGHT(H22,4) -> 0515 | J22: 409.12 | K22: 409.12 | L22: =IF(N22<=0, N22, 0) -> 0 | M22: =IF(N22>=0, N22, 0) -> 0.02 | N22: 0.02
G23: 22 | H23: 20250922 0530 | I23: =RIGHT(H23,4) -> 0530 | J23: 404 | K23: 404 | L23: =IF(N23<=0, N23, 0) -> 0 | M23: =IF(N23>=0, N23, 0) -> 0 | N23: 0
G24: 23 | H24: 20250922 0545 | I24: =RIGHT(H24,4) -> 0545 | J24: 381.48 | K24: 381.48 | L24: =IF(N24<=0, N24, 0) -> 0 | M24: =IF(N24>=0, N24, 0) -> 0 | N24: 0
A25: 充电电量（MWh) | B25: =SUM(L:L)/4 -> -181.27 | C25: 放电电量（MWh) | D25: =SUM(M:M)/4 -> 170.885 | G25: 24 | H25: 20250922 0600 | I25: =RIGHT(H25,4) -> 0600 | J25: 374 | K25: 374 | L25: =IF(N25<=0, N25, 0) -> 0 | M25: =IF(N25>=0, N25, 0) -> 0 | N25: 0
A26: 充电均价(元/MWh） | B26: =B27/B25 -> -79.964219 | C26: 放电均价(元/MWh） | D26: =D27/D25 -> 614.65436 | G26: 25 | H26: 20250922 0615 | I26: =RIGHT(H26,4) -> 0615 | J26: 359 | K26: 359 | L26: =IF(N26<=0, N26, 0) -> 0 | M26: =IF(N26>=0, N26, 0) -> 0 | N26: 0
A27: 充电费用（元,正数代表收入） | B27: =SUMPRODUCT(J:J,L:L)/4 -> 14495.114 | C27: 放电收益（元,正数代表收入） | D27: {=SUMPRODUCT(K:K,M:M)/4} -> 105035.21 | G27: 26 | H27: 20250922 0630 | I27: =RIGHT(H27,4) -> 0630 | J27: 361 | K27: 361 | L27: =IF(N27<=0, N27, 0) -> 0 | M27: =IF(N27>=0, N27, 0) -> 0 | N27: 0
A28: 充放电价差(元/MWh） | B28: =D26-B26 -> 694.61858 | C28: 充放电收益(元/MWh） | D28: =D27+B27 -> 119530.32 | G28: 27 | H28: 20250922 0645 | I28: =RIGHT(H28,4) -> 0645 | J28: 364 | K28: 364 | L28: =IF(N28<=0, N28, 0) -> 0 | M28: =IF(N28>=0, N28, 0) -> 0 | N28: 0
G29: 28 | H29: 20250922 0700 | I29: =RIGHT(H29,4) -> 0700 | J29: 316 | K29: 316 | L29: =IF(N29<=0, N29, 0) -> 0 | M29: =IF(N29>=0, N29, 0) -> 0 | N29: 0
D30: =[1]充放测算!O4 -> 81275.27 | G30: 29 | H30: 20250922 0715 | I30: =RIGHT(H30,4) -> 0715 | J30: -80 | K30: -80 | L30: =IF(N30<=0, N30, 0) -> 0 | M30: =IF(N30>=0, N30, 0) -> 0 | N30: 0
G31: 30 | H31: 20250922 0730 | I31: =RIGHT(H31,4) -> 0730 | J31: -80 | K31: -80 | L31: =IF(N31<=0, N31, 0) -> 0 | M31: =IF(N31>=0, N31, 0) -> 0 | N31: 0
G32: 31 | H32: 20250922 0745 | I32: =RIGHT(H32,4) -> 0745 | J32: -80 | K32: -80 | L32: =IF(N32<=0, N32, 0) -> 0 | M32: =IF(N32>=0, N32, 0) -> 0 | N32: 0
G33: 32 | H33: 20250922 0800 | I33: =RIGHT(H33,4) -> 0800 | J33: -80 | K33: -80 | L33: =IF(N33<=0, N33, 0) -> 0 | M33: =IF(N33>=0, N33, 0) -> 0 | N33: 0
A34: 序号 | B34: 类型 | C34: 开始出力（MW） | D34: 结束出力（MW） | E34: 报价(元/MWh) | G34: 33 | H34: 20250922 0815 | I34: =RIGHT(H34,4) -> 0815 | J34: -80 | K34: -80 | L34: =IF(N34<=0, N34, 0) -> 0 | M34: =IF(N34>=0, N34, 0) -> 0 | N34: 0
G35: 34 | H35: 20250922 0830 | I35: =RIGHT(H35,4) -> 0830 | J35: -80 | K35: -80 | L35: =IF(N35<=0, N35, 0) -> 0 | M35: =IF(N35>=0, N35, 0) -> 0 | N35: 0
A36: 1 | B36: 充电 | C36: -100 | D36: -95 | E36: 0 | G36: 35 | H36: 20250922 0845 | I36: =RIGHT(H36,4) -> 0845 | J36: -80 | K36: -80 | L36: =IF(N36<=0, N36, 0) -> 0 | M36: =IF(N36>=0, N36, 0) -> 0 | N36: 0
A37: 2 | B37: 充电 | C37: -95 | D37: 0 | E37: 150 | G37: 36 | H37: 20250922 0900 | I37: =RIGHT(H37,4) -> 0900 | J37: -80 | K37: -80 | L37: =IF(N37<=0, N37, 0) -> 0 | M37: =IF(N37>=0, N37, 0) -> 0 | N37: 0
A38: 3 | B38: 放电 | C38: 0 | D38: 95 | E38: 280 | G38: 37 | H38: 20250922 0915 | I38: =RIGHT(H38,4) -> 0915 | J38: -80 | K38: -80 | L38: =IF(N38<=0, N38, 0) -> 0 | M38: =IF(N38>=0, N38, 0) -> 0 | N38: 0
A39: 4 | B39: 放电 | C39: 95 | D39: 100 | E39: 350 | G39: 38 | H39: 20250922 0930 | I39: =RIGHT(H39,4) -> 0930 | J39: -80 | K39: -80 | L39: =IF(N39<=0, N39, 0) -> 0 | M39: =IF(N39>=0, N39, 0) -> 0 | N39: 0
G40: 39 | H40: 20250922 0945 | I40: =RIGHT(H40,4) -> 0945 | J40: -80 | K40: -80 | L40: =IF(N40<=0, N40, 0) -> 0 | M40: =IF(N40>=0, N40, 0) -> 0 | N40: 0
...

Sheet 容量分摊系数
A1: 容量电价 | C1: 70.5
A3: 容量分摊--算数平均 系数 | C3: {=SUMPRODUCT(C8:C103,D8:D103)/SUM(C8:C103)} -> 0.325 | E3: 容量分摊系数--电量加权 | G3: {=SUMPRODUCT(D8:D103,E8:E103)/SUM(E8:E103)} -> 0.11624786
A6: 时点 | B6: 刻钟点 | C6: 是否充电 | D6: 当前月份 | E6: 充电电量 | F6: 容量分摊系数（2026年）
D7: 3月 | F7: 1月 | G7: 2月 | H7: 3月 | I7: 4月 | J7: 5月 | K7: 6月 | L7: 7月 | M7: 8月 | N7: 9月 | O7: 10月 | P7: 11月 | Q7: 12月
A8: 1 | B8: 1 | C8: =IF(E8<0,1,0) -> 1 | D8: {=INDIRECT(ADDRESS(B8+ROW($D$7),MATCH($D$7,$F$7:$Q$7,0)+5))} -> 1 | E8: =报价及预中标!L2 -> -0.05 | F8: 1 | G8: 1 | H8: 1 | I8: 1 | J8: 1 | K8: 1 | L8: 0.3 | M8: 0.3 | N8: 1 | O8: 1 | P8: 1 | Q8: 1
B9: 2 | C9: =IF(E9<0,1,0) -> 0 | D9: {=INDIRECT(ADDRESS(B9+ROW($D$7),MATCH($D$7,$F$7:$Q$7,0)+5))} -> 1 | E9: =报价及预中标!L3 -> 0 | F9: 1 | G9: 1 | H9: 1 | I9: 1 | J9: 1 | K9: 1 | L9: 0.3 | M9: 0.3 | N9: 1 | O9: 1 | P9: 1 | Q9: 1
B10: 3 | C10: =IF(E10<0,1,0) -> 0 | D10: {=INDIRECT(ADDRESS(B10+ROW($D$7),MATCH($D$7,$F$7:$Q$7,0)+5))} -> 1 | E10: =报价及预中标!L4 -> 0 | F10: 1 | G10: 1 | H10: 1 | I10: 1 | J10: 1 | K10: 1 | L10: 0.3 | M10: 0.3 | N10: 1 | O10: 1 | P10: 1 | Q10: 1
B11: 4 | C11: =IF(E11<0,1,0) -> 0 | D11: {=INDIRECT(ADDRESS(B11+ROW($D$7),MATCH($D$7,$F$7:$Q$7,0)+5))} -> 1 | E11: =报价及预中标!L5 -> 0 | F11: 1 | G11: 1 | H11: 1 | I11: 1 | J11: 1 | K11: 1 | L11: 0.3 | M11: 0.3 | N11: 1 | O11: 1 | P11: 1 | Q11: 1
A12: 2 | B12: 5 | C12: =IF(E12<0,1,0) -> 0 | D12: {=INDIRECT(ADDRESS(B12+ROW($D$7),MATCH($D$7,$F$7:$Q$7,0)+5))} -> 1 | E12: =报价及预中标!L6 -> 0 | F12: 0.3 | G12: 0.3 | H12: 1 | I12: 1 | J12: 1 | K12: 1 | L12: 0.3 | M12: 0.3 | N12: 1 | O12: 1 | P12: 1 | Q12: 0.3
B13: 6 | C13: =IF(E13<0,1,0) -> 0 | D13: {=INDIRECT(ADDRESS(B13+ROW($D$7),MATCH($D$7,$F$7:$Q$7,0)+5))} -> 1 | E13: =报价及预中标!L7 -> 0 | F13: 0.3 | G13: 0.3 | H13: 1 | I13: 1 | J13: 1 | K13: 1 | L13: 0.3 | M13: 0.3 | N13: 1 | O13: 1 | P13: 1 | Q13: 0.3
B14: 7 | C14: =IF(E14<0,1,0) -> 0 | D14: {=INDIRECT(ADDRESS(B14+ROW($D$7),MATCH($D$7,$F$7:$Q$7,0)+5))} -> 1 | E14: =报价及预中标!L8 -> 0 | F14: 0.3 | G14: 0.3 | H14: 1 | I14: 1 | J14: 1 | K14: 1 | L14: 0.3 | M14: 0.3 | N14: 1 | O14: 1 | P14: 1 | Q14: 0.3
B15: 8 | C15: =IF(E15<0,1,0) -> 0 | D15: {=INDIRECT(ADDRESS(B15+ROW($D$7),MATCH($D$7,$F$7:$Q$7,0)+5))} -> 1 | E15: =报价及预中标!L9 -> 0 | F15: 0.3 | G15: 0.3 | H15: 1 | I15: 1 | J15: 1 | K15: 1 | L15: 0.3 | M15: 0.3 | N15: 1 | O15: 1 | P15: 1 | Q15: 0.3
A16: 3 | B16: 9 | C16: =IF(E16<0,1,0) -> 0 | D16: {=INDIRECT(ADDRESS(B16+ROW($D$7),MATCH($D$7,$F$7:$Q$7,0)+5))} -> 1 | E16: =报价及预中标!L10 -> 0 | F16: 0.3 | G16: 0.3 | H16: 1 | I16: 1 | J16: 1 | K16: 1 | L16: 0.3 | M16: 0.3 | N16: 1 | O16: 1 | P16: 1 | Q16: 0.3
B17: 10 | C17: =IF(E17<0,1,0) -> 0 | D17: {=INDIRECT(ADDRESS(B17+ROW($D$7),MATCH($D$7,$F$7:$Q$7,0)+5))} -> 1 | E17: =报价及预中标!L11 -> 0 | F17: 0.3 | G17: 0.3 | H17: 1 | I17: 1 | J17: 1 | K17: 1 | L17: 0.3 | M17: 0.3 | N17: 1 | O17: 1 | P17: 1 | Q17: 0.3
B18: 11 | C18: =IF(E18<0,1,0) -> 0 | D18: {=INDIRECT(ADDRESS(B18+ROW($D$7),MATCH($D$7,$F$7:$Q$7,0)+5))} -> 1 | E18: =报价及预中标!L12 -> 0 | F18: 0.3 | G18: 0.3 | H18: 1 | I18: 1 | J18: 1 | K18: 1 | L18: 0.3 | M18: 0.3 | N18: 1 | O18: 1 | P18: 1 | Q18: 0.3
B19: 12 | C19: =IF(E19<0,1,0) -> 0 | D19: {=INDIRECT(ADDRESS(B19+ROW($D$7),MATCH($D$7,$F$7:$Q$7,0)+5))} -> 1 | E19: =报价及预中标!L13 -> 0 | F19: 0.3 | G19: 0.3 | H19: 1 | I19: 1 | J19: 1 | K19: 1 | L19: 0.3 | M19: 0.3 | N19: 1 | O19: 1 | P19: 1 | Q19: 0.3
A20: 4 | B20: 13 | C20: =IF(E20<0,1,0) -> 0 | D20: {=INDIRECT(ADDRESS(B20+ROW($D$7),MATCH($D$7,$F$7:$Q$7,0)+5))} -> 1 | E20: =报价及预中标!L14 -> 0 | F20: 0.3 | G20: 0.3 | H20: 1 | I20: 1 | J20: 1 | K20: 1 | L20: 0.3 | M20: 0.3 | N20: 1 | O20: 1 | P20: 1 | Q20: 0.3
B21: 14 | C21: =IF(E21<0,1,0) -> 0 | D21: {=INDIRECT(ADDRESS(B21+ROW($D$7),MATCH($D$7,$F$7:$Q$7,0)+5))} -> 1 | E21: =报价及预中标!L15 -> 0 | F21: 0.3 | G21: 0.3 | H21: 1 | I21: 1 | J21: 1 | K21: 1 | L21: 0.3 | M21: 0.3 | N21: 1 | O21: 1 | P21: 1 | Q21: 0.3
B22: 15 | C22: =IF(E22<0,1,0) -> 0 | D22: {=INDIRECT(ADDRESS(B22+ROW($D$7),MATCH($D$7,$F$7:$Q$7,0)+5))} -> 1 | E22: =报价及预中标!L16 -> 0 | F22: 0.3 | G22: 0.3 | H22: 1 | I22: 1 | J22: 1 | K22: 1 | L22: 0.3 | M22: 0.3 | N22: 1 | O22: 1 | P22: 1 | Q22: 0.3
B23: 16 | C23: =IF(E23<0,1,0) -> 0 | D23: {=INDIRECT(ADDRESS(B23+ROW($D$7),MATCH($D$7,$F$7:$Q$7,0)+5))} -> 1 | E23: =报价及预中标!L17 -> 0 | F23: 0.3 | G23: 0.3 | H23: 1 | I23: 1 | J23: 1 | K23: 1 | L23: 0.3 | M23: 0.3 | N23: 1 | O23: 1 | P23: 1 | Q23: 0.3
A24: 5 | B24: 17 | C24: =IF(E24<0,1,0) -> 0 | D24: {=INDIRECT(ADDRESS(B24+ROW($D$7),MATCH($D$7,$F$7:$Q$7,0)+5))} -> 1 | E24: =报价及预中标!L18 -> 0 | F24: 0.3 | G24: 0.3 | H24: 1 | I24: 1 | J24: 1 | K24: 1 | L24: 0.3 | M24: 0.3 | N24: 1 | O24: 1 | P24: 1 | Q24: 0.3
B25: 18 | C25: =IF(E25<0,1,0) -> 0 | D25: {=INDIRECT(ADDRESS(B25+ROW($D$7),MATCH($D$7,$F$7:$Q$7,0)+5))} -> 1 | E25: =报价及预中标!L19 -> 0 | F25: 0.3 | G25: 0.3 | H25: 1 | I25: 1 | J25: 1 | K25: 1 | L25: 0.3 | M25: 0.3 | N25: 1 | O25: 1 | P25: 1 | Q25: 0.3
B26: 19 | C26: =IF(E26<0,1,0) -> 0 | D26: {=INDIRECT(ADDRESS(B26+ROW($D$7),MATCH($D$7,$F$7:$Q$7,0)+5))} -> 1 | E26: =报价及预中标!L20 -> 0 | F26: 0.3 | G26: 0.3 | H26: 1 | I26: 1 | J26: 1 | K26: 1 | L26: 0.3 | M26: 0.3 | N26: 1 | O26: 1 | P26: 1 | Q26: 0.3
B27: 20 | C27: =IF(E27<0,1,0) -> 0 | D27: {=INDIRECT(ADDRESS(B27+ROW($D$7),MATCH($D$7,$F$7:$Q$7,0)+5))} -> 1 | E27: =报价及预中标!L21 -> 0 | F27: 0.3 | G27: 0.3 | H27: 1 | I27: 1 | J27: 1 | K27: 1 | L27: 0.3 | M27: 0.3 | N27: 1 | O27: 1 | P27: 1 | Q27: 0.3
A28: 6 | B28: 21 | C28: =IF(E28<0,1,0) -> 0 | D28: {=INDIRECT(ADDRESS(B28+ROW($D$7),MATCH($D$7,$F$7:$Q$7,0)+5))} -> 1 | E28: =报价及预中标!L22 -> 0 | F28: 0.3 | G28: 0.3 | H28: 1 | I28: 1 | J28: 1 | K28: 1 | L28: 0.3 | M28: 0.3 | N28: 1 | O28: 1 | P28: 1 | Q28: 0.3
B29: 22 | C29: =IF(E29<0,1,0) -> 0 | D29: {=INDIRECT(ADDRESS(B29+ROW($D$7),MATCH($D$7,$F$7:$Q$7,0)+5))} -> 1 | E29: =报价及预中标!L23 -> 0 | F29: 0.3 | G29: 0.3 | H29: 1 | I29: 1 | J29: 1 | K29: 1 | L29: 0.3 | M29: 0.3 | N29: 1 | O29: 1 | P29: 1 | Q29: 0.3
B30: 23 | C30: =IF(E30<0,1,0) -> 0 | D30: {=INDIRECT(ADDRESS(B30+ROW($D$7),MATCH($D$7,$F$7:$Q$7,0)+5))} -> 1 | E30: =报价及预中标!L24 -> 0 | F30: 0.3 | G30: 0.3 | H30: 1 | I30: 1 | J30: 1 | K30: 1 | L30: 0.3 | M30: 0.3 | N30: 1 | O30: 1 | P30: 1 | Q30: 0.3
B31: 24 | C31: =IF(E31<0,1,0) -> 0 | D31: {=INDIRECT(ADDRESS(B31+ROW($D$7),MATCH($D$7,$F$7:$Q$7,0)+5))} -> 1 | E31: =报价及预中标!L25 -> 0 | F31: 0.3 | G31: 0.3 | H31: 1 | I31: 1 | J31: 1 | K31: 1 | L31: 0.3 | M31: 0.3 | N31: 1 | O31: 1 | P31: 1 | Q31: 0.3
A32: 7 | B32: 25 | C32: =IF(E32<0,1,0) -> 0 | D32: {=INDIRECT(ADDRESS(B32+ROW($D$7),MATCH($D$7,$F$7:$Q$7,0)+5))} -> 1 | E32: =报价及预中标!L26 -> 0 | F32: 1.7 | G32: 1.7 | H32: 1 | I32: 1 | J32: 1 | K32: 0.3 | L32: 1 | M32: 1 | N32: 1 | O32: 1 | P32: 1 | Q32: 1.7
B33: 26 | C33: =IF(E33<0,1,0) -> 0 | D33: {=INDIRECT(ADDRESS(B33+ROW($D$7),MATCH($D$7,$F$7:$Q$7,0)+5))} -> 1 | E33: =报价及预中标!L27 -> 0 | F33: 1.7 | G33: 1.7 | H33: 1 | I33: 1 | J33: 1 | K33: 0.3 | L33: 1 | M33: 1 | N33: 1 | O33: 1 | P33: 1 | Q33: 1.7
B34: 27 | C34: =IF(E34<0,1,0) -> 0 | D34: {=INDIRECT(ADDRESS(B34+ROW($D$7),MATCH($D$7,$F$7:$Q$7,0)+5))} -> 1 | E34: =报价及预中标!L28 -> 0 | F34: 1.7 | G34: 1.7 | H34: 1 | I34: 1 | J34: 1 | K34: 0.3 | L34: 1 | M34: 1 | N34: 1 | O34: 1 | P34: 1 | Q34: 1.7
B35: 28 | C35: =IF(E35<0,1,0) -> 0 | D35: {=INDIRECT(ADDRESS(B35+ROW($D$7),MATCH($D$7,$F$7:$Q$7,0)+5))} -> 1 | E35: =报价及预中标!L29 -> 0 | F35: 1.7 | G35: 1.7 | H35: 1 | I35: 1 | J35: 1 | K35: 0.3 | L35: 1 | M35: 1 | N35: 1 | O35: 1 | P35: 1 | Q35: 1.7
A36: 8 | B36: 29 | C36: =IF(E36<0,1,0) -> 0 | D36: {=INDIRECT(ADDRESS(B36+ROW($D$7),MATCH($D$7,$F$7:$Q$7,0)+5))} -> 1 | E36: =报价及预中标!L30 -> 0 | F36: 1.7 | G36: 1.7 | H36: 1 | I36: 1 | J36: 1 | K36: 0.3 | L36: 1 | M36: 1 | N36: 1 | O36: 1 | P36: 1 | Q36: 1.7
B37: 30 | C37: =IF(E37<0,1,0) -> 0 | D37: {=INDIRECT(ADDRESS(B37+ROW($D$7),MATCH($D$7,$F$7:$Q$7,0)+5))} -> 1 | E37: =报价及预中标!L31 -> 0 | F37: 1.7 | G37: 1.7 | H37: 1 | I37: 1 | J37: 1 | K37: 0.3 | L37: 1 | M37: 1 | N37: 1 | O37: 1 | P37: 1 | Q37: 1.7
B38: 31 | C38: =IF(E38<0,1,0) -> 0 | D38: {=INDIRECT(ADDRESS(B38+ROW($D$7),MATCH($D$7,$F$7:$Q$7,0)+5))} -> 1 | E38: =报价及预中标!L32 -> 0 | F38: 1.7 | G38: 1.7 | H38: 1 | I38: 1 | J38: 1 | K38: 0.3 | L38: 1 | M38: 1 | N38: 1 | O38: 1 | P38: 1 | Q38: 1.7
B39: 32 | C39: =IF(E39<0,1,0) -> 0 | D39: {=INDIRECT(ADDRESS(B39+ROW($D$7),MATCH($D$7,$F$7:$Q$7,0)+5))} -> 1 | E39: =报价及预中标!L33 -> 0 | F39: 1.7 | G39: 1.7 | H39: 1 | I39: 1 | J39: 1 | K39: 0.3 | L39: 1 | M39: 1 | N39: 1 | O39: 1 | P39: 1 | Q39: 1.7
A40: 9 | B40: 33 | C40: =IF(E40<0,1,0) -> 0 | D40: {=INDIRECT(ADDRESS(B40+ROW($D$7),MATCH($D$7,$F$7:$Q$7,0)+5))} -> 1 | E40: =报价及预中标!L34 -> 0 | F40: 1.7 | G40: 1.7 | H40: 1 | I40: 1 | J40: 1 | K40: 0.3 | L40: 1 | M40: 1 | N40: 1 | O40: 1 | P40: 1 | Q40: 1.7
B41: 34 | C41: =IF(E41<0,1,0) -> 0 | D41: {=INDIRECT(ADDRESS(B41+ROW($D$7),MATCH($D$7,$F$7:$Q$7,0)+5))} -> 1 | E41: =报价及预中标!L35 -> 0 | F41: 1.7 | G41: 1.7 | H41: 1 | I41: 1 | J41: 1 | K41: 0.3 | L41: 1 | M41: 1 | N41: 1 | O41: 1 | P41: 1 | Q41: 1.7
B42: 35 | C42: =IF(E42<0,1,0) -> 0 | D42: {=INDIRECT(ADDRESS(B42+ROW($D$7),MATCH($D$7,$F$7:$Q$7,0)+5))} -> 1 | E42: =报价及预中标!L36 -> 0 | F42: 1.7 | G42: 1.7 | H42: 1 | I42: 1 | J42: 1 | K42: 0.3 | L42: 1 | M42: 1 | N42: 1 | O42: 1 | P42: 1 | Q42: 1.7
B43: 36 | C43: =IF(E43<0,1,0) -> 0 | D43: {=INDIRECT(ADDRESS(B43+ROW($D$7),MATCH($D$7,$F$7:$Q$7,0)+5))} -> 1 | E43: =报价及预中标!L37 -> 0 | F43: 1.7 | G43: 1.7 | H43: 1 | I43: 1 | J43: 1 | K43: 0.3 | L43: 1 | M43: 1 | N43: 1 | O43: 1 | P43: 1 | Q43: 1.7
...
